Workbook

Sheet PORTADA
A1: ⚽ PENCA DEL MUNDIAL FIFA 2026
A2: Sistema de Gestión · Hoja de Cálculo v1.0
A4: INSTRUCCIONES DE USO
A6: 1 | B6: PARTICIPANTES | D6: Registrá los participantes de la penca en la hoja PARTICIPANTES (columnas A y B).
A7: 2 | B7: PARTIDOS | D7: Los 48 partidos de la fase de grupos ya están cargados en la hoja PARTIDOS.
A8: 3 | B8: PRONÓSTICOS | D8: En la hoja PRONÓSTICOS ingresá el marcador pronosticado por cada participante.
A9: 4 | B9: RESULTADOS | D9: Cuando termine un partido, ingresá el resultado real en la hoja RESULTADOS.
A10: 5 | B10: PUNTAJES | D10: Los puntajes se calculan automáticamente en la hoja PUNTAJES al ingresar resultados.
A11: 6 | B11: CLASIFICACIÓN | D11: La tabla de posiciones se actualiza automáticamente en la hoja CLASIFICACIÓN.
A14: SISTEMA DE PUNTUACIÓN
A15: ⭐ EXACTO | B15: 3 puntos | D15: Acertás el marcador exacto (ej: pronóstico 2-1, resultado 2-1)
A16: ✓ DIFERENCIA | B16: 2 puntos | D16: La diferencia de goles es correcta y hay ganador (ej: pron 3-1, res 2-0)
A17: ✓ GANADOR | B17: 1 punto | D17: Acertás quién gana o si hay empate (pero no diferencia ni marcador)
A18: ✗ INCORRECTO | B18: 0 puntos | D18: El pronóstico no coincide con ninguna categoría anterior

Sheet PARTICIPANTES
A1: REGISTRO DE PARTICIPANTES
A2: # | B2: NOMBRE COMPLETO | C2: EMAIL | D2: FECHA REGISTRO | E2: ACTIVO
A3: 1 | B3: Ana García | C3: ana@email.com | D3: 11/06/2026 | E3: SÍ
A4: 2 | B4: Bruno Pérez | C4: bruno@email.com | D4: 11/06/2026 | E4: SÍ
A5: 3 | B5: Carla López | C5: carla@email.com | D5: 11/06/2026 | E5: SÍ
A6: 4 | B6: Diego Martínez | C6: diego@email.com | D6: 11/06/2026 | E6: SÍ
A7: 5 | B7: Elena Rodríguez | C7: elena@email.com | D7: 11/06/2026 | E7: SÍ
A8: 6
A9: 7
A10: 8
A11: 9
A12: 10
A13: 11
A14: 12
A15: 13
A16: 14
A17: 15
A18: 16
A19: 17
... A27: 25

Sheet PARTIDOS
A1: PARTIDOS — FASE DE GRUPOS MUNDIAL 2026
A2: # | B2: GRUPO | C2: EQUIPO LOCAL | D2: EQUIPO VISITANTE | E2: FECHA | F2: HORA | G2: ESTADIO | H2: CIUDAD/PAÍS
A3: 1 | B3: A | C3: Estados Unidos | D3: Canadá | E3: 11/06/2026 | F3: 18:00 | G3: SoFi Stadium | H3: Los Ángeles, USA
A4: 2 | B4: A | C4: Uruguay | D4: Estados Unidos | E4: 15/06/2026 | F4: 15:00 | G4: Hard Rock Stadium | H4: Miami, USA
A5: 3 | B5: A | C5: Canadá | D5: Uruguay | E5: 19/06/2026 | F5: 12:00 | G5: Levi's Stadium | H5: San Francisco, USA
A6: 4 | B6: B | C6: México | D6: Ecuador | E6: 11/06/2026 | F6: 21:00 | G6: AT&T Stadium | H6: Dallas, USA
A7: 5 | B7: B | C7: Jamaica | D7: México | E7: 15/06/2026 | F7: 18:00 | G7: Estadio Azteca | H7: Ciudad de México, MEX
A8: 6 | B8: B | C8: Ecuador | D8: Jamaica | E8: 19/06/2026 | F8: 15:00 | G8: BMO Field | H8: Toronto, CAN
A9: 7 | B9: C | C9: Argentina | D9: Chile | E9: 12/06/2026 | F9: 12:00 | G9: MetLife Stadium | H9: Nueva York, USA
A10: 8 | B10: C | C10: Albania | D10: Argentina | E10: 16/06/2026 | F10: 12:00 | G10: Rose Bowl | H10: Los Ángeles, USA
A11: 9 | B11: C | C11: Chile | D11: Albania | E11: 20/06/2026 | F11: 12:00 | G11: Lumen Field | H11: Seattle, USA
A12: 10 | B12: D | C12: Brasil | D12: Colombia | E12: 12/06/2026 | F12: 15:00 | G12: Gillette Stadium | H12: Boston, USA
A13: 11 | B13: D | C13: Panamá | D13: Brasil | E13: 16/06/2026 | F13: 15:00 | G13: Arrowhead Stadium | H13: Kansas City, USA
A14: 12 | B14: D | C14: Colombia | D14: Panamá | E14: 20/06/2026 | F14: 15:00 | G14: Est. Universitario | H14: Monterrey, MEX
... A50: 48 | B50: P | C50: Perú | D50: Bolivia | E50: 23/06/2026 | F50: 15:00 | G50: Lumen Field | H50: Seattle, USA

Sheet RESULTADOS
A1: RESULTADOS REALES — INGRESAR AL FINALIZAR CADA PARTIDO
A2: ▶ Ingresá el resultado real en las columnas GOLES LOCAL y GOLES VISITANTE. Los puntajes se calculan automáticamente.
A3: # | B3: LOCAL | C3: VISITANTE | D3: GRUPO | E3: GOLES LOCAL ▼ | F3: GOLES VISIT. ▼ | G3: ESTADO
A4: 1 | B4: Estados Unidos | C4: Canadá | D4: A | E4: 0 | F4: 0 | G4: =IF(E4=""," Sin resultado","✓ Ingresado")
A5: 2 | B5: Uruguay | C5: Estados Unidos | D5: A | E5: 0 | F5: 0 | G5: =IF(E5=""," Sin resultado","✓ Ingresado")
A6: 3 | B6: Canadá | C6: Uruguay | D6: A | E6: 0 | F6: 0 | G6: =IF(E6=""," Sin resultado","✓ Ingresado")
A7: 4 | B7: México | C7: Ecuador | D7: B | E7: 0 | F7: 0 | G7: =IF(E7=""," Sin resultado","✓ Ingresado")
A8: 5 | B8: Jamaica | C8: México | D8: B | E8: 0 | F8: 0 | G8: =IF(E8=""," Sin resultado","✓ Ingresado")
A9: 6 | B9: Ecuador | C9: Jamaica | D9: B | E9: 0 | F9: 0 | G9: =IF(E9=""," Sin resultado","✓ Ingresado")
A10: 7 | B10: Argentina | C10: Chile | D10: C | E10: 0 | F10: 0 | G10: =IF(E10=""," Sin resultado","✓ Ingresado")
A11: 8 | B11: Albania | C11: Argentina | D11: C | E11: 0 | F11: 0 | G11: =IF(E11=""," Sin resultado","✓ Ingresado")
A12: 9 | B12: Chile | C12: Albania | D12: C | E12: 0 | F12: 0 | G12: =IF(E12=""," Sin resultado","✓ Ingresado")
A13: 10 | B13: Brasil | C13: Colombia | D13: D | E13: 0 | F13: 0 | G13: =IF(E13=""," Sin resultado","✓ Ingresado")
A14: 11 | B14: Panamá | C14: Brasil | D14: D | E14: 0 | F14: 0 | G14: =IF(E14=""," Sin resultado","✓ Ingresado")
A15: 12 | B15: Colombia | C15: Panamá | D15: D | E15: 0 | F15: 0 | G15: =IF(E15=""," Sin resultado","✓ Ingresado")
... A51: 48 | B51: Perú | C51: Bolivia | D51: P | E51: 0 | F51: 0 | G51: =IF(E51=""," Sin resultado","✓ Ingresado")

Sheet PRONÓSTICOS
A1: PRONÓSTICOS POR PARTICIPANTE — Formato: GolesLocal-GolesVisitante
A2: ▶ Columnas C en adelante: ingresar pronóstico para cada participante. Ejemplo: 2-1 significa que el local gana 2 a 1.
A3: # | B3: PARTIDO | C3: Ana García | D3: Bruno Pérez | E3: Carla López | F3: Diego M. | G3: Elena R. | H3: Felipe S. | I3: Gabriela T. | J3: Hernán V. | K3: Isabel W. | L3: Juan X.
A4: 1 | B4: Estados Unidos vs Canadá | C4: 1-0 | D4: 2-1 | E4: 1-1 | F4: 2-0 | G4: 2-0 | H4: 0-0 | I4: 1-0 | J4: 2-2 | K4: 1-0 | L4: 3-0
A5: 2 | B5: Uruguay vs Estados Unidos | C5: 0-1 | D5: 2-1 | E5: 2-1 | F5: 1-0 | G5: 2-0 | H5: 2-0 | I5: 2-2 | J5: 3-0 | K5: 2-1 | L5: 2-2
A6: 3 | B6: Canadá vs Uruguay | C6: 2-0 | D6: 2-2 | E6: 0-1 | F6: 2-0 | G6: 1-2 | H6: 3-0 | I6: 1-1 | J6: 2-1 | K6: 0-0 | L6: 0-1
A7: 4 | B7: México vs Ecuador | C7: 3-1 | D7: 1-1 | E7: 0-0 | F7: 2-0 | G7: 3-1 | H7: 1-0 | I7: 1-0 | J7: 0-1 | K7: 1-0 | L7: 3-1
A8: 5 | B8: Jamaica vs México | C8: 3-1 | D8: 3-0 | E8: 1-1 | F8: 2-1 | G8: 1-2 | H8: 2-2 | I8: 1-0 | J8: 0-1 | K8: 1-0 | L8: 2-2
A9: 6 | B9: Ecuador vs Jamaica | C9: 1-1 | D9: 3-0 | E9: 3-1 | F9: 3-0 | G9: 2-0 | H9: 1-0 | I9: 2-1 | J9: 2-0 | K9: 1-1 | L9: 1-0
A10: 7 | B10: Argentina vs Chile | C10: 2-0 | D10: 1-0 | E10: 0-1 | F10: 1-1 | G10: 1-2 | H10: 3-1 | I10: 0-0 | J10: 3-1 | K10: 3-1 | L10: 2-0
A11: 8 | B11: Albania vs Argentina | C11: 1-1 | D11: 1-0 | E11: 3-0 | F11: 0-0 | G11: 2-2 | H11: 2-0 | I11: 0-0 | J11: 1-2 | K11: 0-1 | L11: 1-1
A12: 9 | B12: Chile vs Albania | C12: 2-2 | D12: 2-0 | E12: 3-1 | F12: 2-1 | G12: 2-0 | H12: 2-1 | I12: 3-1 | J12: 0-1 | K12: 1-1 | L12: 1-0
A13: 10 | B13: Brasil vs Colombia | C13: 2-0 | D13: 3-0 | E13: 3-1 | F13: 2-0 | G13: 1-2 | H13: 0-1 | I13: 1-2 | J13: 0-0 | K13: 1-1 | L13: 0-0
A14: 11 | B14: Panamá vs Brasil | C14: 2-0 | D14: 2-2 | E14: 2-2 | F14: 1-1 | G14: 3-0 | H14: 0-1 | I14: 3-0 | J14: 0-1 | K14: 3-1 | L14: 2-0
A15: 12 | B15: Colombia vs Panamá | C15: 0-0 | D15: 2-2 | E15: 1-2 | F15: 1-0 | G15: 2-1 | H15: 1-0 | I15: 0-0 | J15: 0-0 | K15: 0-1 | L15: 3-0
... A51: 48 | B51: Perú vs Bolivia | C51: 1-1 | D51: 0-1 | E51: 3-1 | F51: 0-1 | G51: 1-1 | H51: 2-2 | I51: 0-0 | J51: 2-0 | K51: 0-1 | L51: 0-1

Sheet PUNTAJES
A1: PUNTAJES CALCULADOS AUTOMÁTICAMENTE
A2: # | B2: PARTIDO | C2: Ana García | D2: Bruno Pérez | E2: Carla López | F2: Diego M. | G2: Elena R. | H2: Felipe S. | I2: Gabriela T. | J2: Hernán V. | K2: Isabel W. | L2: Juan X.
A3: 1 | B3: Estados Unidos vs Canadá | C3: =IF(OR(RESULTADOS!E4="",RESULTADOS!E4=0,RESULTADOS!F4=""),"—",IF(AND(VALUE(LEFT(PRONÓSTICOS!C4,FIND("-",PRONÓSTICOS!C4)-1))=RESULTADOS!E4,VALUE(MID(PRONÓSTICOS!C4,FIND("-",PRONÓSTICOS!C4)+1,10))=RESULTADOS!F4),3,IF(AND(VALUE(LEFT(PRONÓSTICOS!C4,FIND("-",PRONÓSTICOS!C4)-1))-VALUE(MID(PRONÓSTICOS!C4,FIND("-",PRONÓSTICOS!C4)+1,10))=RESULTADOS!E4-RESULTADOS!F4,VALUE(LEFT(PRONÓSTICOS!C4,FIND("-",PRONÓSTICOS!C4)-1))<>RESULTADOS!E4),2,IF(SIGN(VALUE(LEFT(PRONÓSTICOS!C4,FIND("-",PRONÓSTICOS!C4)-1))-VALUE(MID(PRONÓSTICOS!C4,FIND("-",PRONÓSTICOS!C4)+1,10)))=SIGN(RESULTADOS!E4-RESULTADOS!F4),1,0)))) | D3: =IF(OR(RESULTADOS!E4="",RESULTADOS!E4=0,RESULTADOS!F4=""),"—",IF(AND(VALUE(LEFT(PRONÓSTICOS!D4,FIND("-",PRONÓSTICOS!D4)-1))=RESULTADOS!E4,VALUE(MID(PRONÓSTICOS!D4,FIND("-",PRONÓSTICOS!D4)+1,10))=RESULTADOS!F4),3,IF(AND(VALUE(LEFT(PRONÓSTICOS!D4,FIND("-",PRONÓSTICOS!D4)-1))-VALUE(MID(PRONÓSTICOS!D4,FIND("-",PRONÓSTICOS!D4)+1,10))=RESULTADOS!E4-RESULTADOS!F4,VALUE(LEFT(PRONÓSTICOS!D4,FIND("-",PRONÓSTICOS!D4)-1))<>RESULTADOS!E4),2,IF(SIGN(VALUE(LEFT(PRONÓSTICOS!D4,FIND("-",PRONÓSTICOS!D4)-1))-VALUE(MID(PRONÓSTICOS!D4,FIND("-",PRONÓSTICOS!D4)+1,10)))=SIGN(RESULTADOS!E4-RESULTADOS!F4),1,0)))) | E3: =IF(OR(RESULTADOS!E4="",RESULTADOS!E4=0,RESULTADOS!F4=""),"—",IF(AND(VALUE(LEFT(PRONÓSTICOS!E4,FIND("-",PRONÓSTICOS!E4)-1))=RESULTADOS!E4,VALUE(MID(PRONÓSTICOS!E4,FIND("-",PRONÓSTICOS!E4)+1,10))=RESULTADOS!F4),3,IF(AND(VALUE(LEFT(PRONÓSTICOS!E4,FIND("-",PRONÓSTICOS!E4)-1))-VALUE(MID(PRONÓSTICOS!E4,FIND("-",PRONÓSTICOS!E4)+1,10))=RESULTADOS!E4-RESULTADOS!F4,VALUE(LEFT(PRONÓSTICOS!E4,FIND("-",PRONÓSTICOS!E4)-1))<>RESULTADOS!E4),2,IF(SIGN(VALUE(LEFT(PRONÓSTICOS!E4,FIND("-",PRONÓSTICOS!E4)-1))-VALUE(MID(PRONÓSTICOS!E4,FIND("-",PRONÓSTICOS!E4)+1,10)))=SIGN(RESULTADOS!E4-RESULTADOS!F4),1,0)))) | F3: =IF(OR(RESULTADOS!E4="",RESULTADOS!E4=0,RESULTADOS!F4=""),"—",IF(AND(VALUE(LEFT(PRONÓSTICOS!F4,FIND("-",PRONÓSTICOS!F4)-1))=RESULTADOS!E4,VALUE(MID(PRONÓSTICOS!F4,FIND("-",PRONÓSTICOS!F4)+1,10))=RESULTADOS!F4),3,IF(AND(VALUE(LEFT(PRONÓSTICOS!F4,FIND("-",PRONÓSTICOS!F4)-1))-VALUE(MID(PRONÓSTICOS!F4,FIND("-",PRONÓSTICOS!F4)+1,10))=RESULTADOS!E4-RESULTADOS!F4,VALUE(LEFT(PRONÓSTICOS!F4,FIND("-",PRONÓSTICOS!F4)-1))<>RESULTADOS!E4),2,IF(SIGN(VALUE(LEFT(PRONÓSTICOS!F4,FIND("-",PRONÓSTICOS!F4)-1))-VALUE(MID(PRONÓSTICOS!F4,FIND("-",PRONÓSTICOS!F4)+1,10)))=SIGN(RESULTADOS!E4-RESULTADOS!F4),1,0)))) | G3: =IF(OR(RESULTADOS!E4="",RESULTADOS!E4=0,RESULTADOS!F4=""),"—",IF(AND(VALUE(LEFT(PRONÓSTICOS!G4,FIND("-",PRONÓSTICOS!G4)-1))=RESULTADOS!E4,VALUE(MID(PRONÓSTICOS!G4,FIND("-",PRONÓSTICOS!G4)+1,10))=RESULTADOS!F4),3,IF(AND(VALUE(LEFT(PRONÓSTICOS!G4,FIND("-",PRONÓSTICOS!G4)-1))-VALUE(MID(PRONÓSTICOS!G4,FIND("-",PRONÓSTICOS!G4)+1,10))=RESULTADOS!E4-RESULTADOS!F4,VALUE(LEFT(PRONÓSTICOS!G4,FIND("-",PRONÓSTICOS!G4)-1))<>RESULTADOS!E4),2,IF(SIGN(VALUE(LEFT(PRONÓSTICOS!G4,FIND("-",PRONÓSTICOS!G4)-1))-VALUE(MID(PRONÓSTICOS!G4,FIND("-",PRONÓSTICOS!G4)+1,10)))=SIGN(RESULTADOS!E4-RESULTADOS!F4),1,0)))) | H3: =IF(OR(RESULTADOS!E4="",RESULTADOS!E4=0,RESULTADOS!F4=""),"—",IF(AND(VALUE(LEFT(PRONÓSTICOS!H4,FIND("-",PRONÓSTICOS!H4)-1))=RESULTADOS!E4,VALUE(MID(PRONÓSTICOS!H4,FIND("-",PRONÓSTICOS!H4)+1,10))=RESULTADOS!F4),3,IF(AND(VALUE(LEFT(PRONÓSTICOS!H4,FIND("-",PRONÓSTICOS!H4)-1))-VALUE(MID(PRONÓSTICOS!H4,FIND("-",PRONÓSTICOS!H4)+1,10))=RESULTADOS!E4-RESULTADOS!F4,VALUE(LEFT(PRONÓSTICOS!H4,FIND("-",PRONÓSTICOS!H4)-1))<>RESULTADOS!E4),2,IF(SIGN(VALUE(LEFT(PRONÓSTICOS!H4,FIND("-",PRONÓSTICOS!H4)-1))-VALUE(MID(PRONÓSTICOS!H4,FIND("-",PRONÓSTICOS!H4)+1,10)))=SIGN(RESULTADOS!E4-RESULTADOS!F4),1,0)))) | I3: =IF(OR(RESULTADOS!E4="",RESULTADOS!E4=0,RESULTADOS!F4=""),"—",IF(AND(VALUE(LEFT(PRONÓSTICOS!I4,FIND("-",PRONÓSTICOS!I4)-1))=RESULTADOS!E4,VALUE(MID(PRONÓSTICOS!I4,FIND("-",PRONÓSTICOS!I4)+1,10))=RESULTADOS!F4),3,IF(AND(VALUE(LEFT(PRONÓSTICOS!I4,FIND("-",PRONÓSTICOS!I4)-1))-VALUE(MID(PRONÓSTICOS!I4,FIND("-",PRONÓSTICOS!I4)+1,10))=RESULTADOS!E4-RESULTADOS!F4,VALUE(LEFT(PRONÓSTICOS!I4,FIND("-",PRONÓSTICOS!I4)-1))<>RESULTADOS!E4),2,IF(SIGN(VALUE(LEFT(PRONÓSTICOS!I4,FIND("-",PRONÓSTICOS!I4)-1))-VALUE(MID(PRONÓSTICOS!I4,FIND("-",PRONÓSTICOS!I4)+1,10)))=SIGN(RESULTADOS!E4-RESULTADOS!F4),1,0)))) | J3: =IF(OR(RESULTADOS!E4="",RESULTADOS!E4=0,RESULTADOS!F4=""),"—",IF(AND(VALUE(LEFT(PRONÓSTICOS!J4,FIND("-",PRONÓSTICOS!J4)-1))=RESULTADOS!E4,VALUE(MID(PRONÓSTICOS!J4,FIND("-",PRONÓSTICOS!J4)+1,10))=RESULTADOS!F4),3,IF(AND(VALUE(LEFT(PRONÓSTICOS!J4,FIND("-",PRONÓSTICOS!J4)-1))-VALUE(MID(PRONÓSTICOS!J4,FIND("-",PRONÓSTICOS!J4)+1,10))=RESULTADOS!E4-RESULTADOS!F4,VALUE(LEFT(PRONÓSTICOS!J4,FIND("-",PRONÓSTICOS!J4)-1))<>RESULTADOS!E4),2,IF(SIGN(VALUE(LEFT(PRONÓSTICOS!J4,FIND("-",PRONÓSTICOS!J4)-1))-VALUE(MID(PRONÓSTICOS!J4,FIND("-",PRONÓSTICOS!J4)+1,10)))=SIGN(RESULTADOS!E4-RESULTADOS!F4),1,0)))) | K3: =IF(OR(RESULTADOS!E4="",RESULTADOS!E4=0,RESULTADOS!F4=""),"—",IF(AND(VALUE(LEFT(PRONÓSTICOS!K4,FIND("-",PRONÓSTICOS!K4)-1))=RESULTADOS!E4,VALUE(MID(PRONÓSTICOS!K4,FIND("-",PRONÓSTICOS!K4)+1,10))=RESULTADOS!F4),3,IF(AND(VALUE(LEFT(PRONÓSTICOS!K4,FIND("-",PRONÓSTICOS!K4)-1))-VALUE(MID(PRONÓSTICOS!K4,FIND("-",PRONÓSTICOS!K4)+1,10))=RESULTADOS!E4-RESULTADOS!F4,VALUE(LEFT(PRONÓSTICOS!K4,FIND("-",PRONÓSTICOS!K4)-1))<>RESULTADOS!E4),2,IF(SIGN(VALUE(LEFT(PRONÓSTICOS!K4,FIND("-",PRONÓSTICOS!K4)-1))-VALUE(MID(PRONÓSTICOS!K4,FIND("-",PRONÓSTICOS!K4)+1,10)))=SIGN(RESULTADOS!E4-RESULTADOS!F4),1,0)))) | L3: =IF(OR(RESULTADOS!E4="",RESULTADOS!E4=0,RESULTADOS!F4=""),"—",IF(AND(VALUE(LEFT(PRONÓSTICOS!L4,FIND("-",PRONÓSTICOS!L4)-1))=RESULTADOS!E4,VALUE(MID(PRONÓSTICOS!L4,FIND("-",PRONÓSTICOS!L4)+1,10))=RESULTADOS!F4),3,IF(AND(VALUE(LEFT(PRONÓSTICOS!L4,FIND("-",PRONÓSTICOS!L4)-1))-VALUE(MID(PRONÓSTICOS!L4,FIND("-",PRONÓSTICOS!L4)+1,10))=RESULTADOS!E4-RESULTADOS!F4,VALUE(LEFT(PRONÓSTICOS!L4,FIND("-",PRONÓSTICOS!L4)-1))<>RESULTADOS!E4),2,IF(SIGN(VALUE(LEFT(PRONÓSTICOS!L4,FIND("-",PRONÓSTICOS!L4)-1))-VALUE(MID(PRONÓSTICOS!L4,FIND("-",PRONÓSTICOS!L4)+1,10)))=SIGN(RESULTADOS!E4-RESULTADOS!F4),1,0))))
A4: 2 | B4: Uruguay vs Estados Unidos | C4: =IF(OR(RESULTADOS!E5="",RESULTADOS!E5=0,RESULTADOS!F5=""),"—",IF(AND(VALUE(LEFT(PRONÓSTICOS!C5,FIND("-",PRONÓSTICOS!C5)-1))=RESULTADOS!E5,VALUE(MID(PRONÓSTICOS!C5,FIND("-",PRONÓSTICOS!C5)+1,10))=RESULTADOS!F5),3,IF(AND(VALUE(LEFT(PRONÓSTICOS!C5,FIND("-",PRONÓSTICOS!C5)-1))-VALUE(MID(PRONÓSTICOS!C5,FIND("-",PRONÓSTICOS!C5)+1,10))=RESULTADOS!E5-RESULTADOS!F5,VALUE(LEFT(PRONÓSTICOS!C5,FIND("-",PRONÓSTICOS!C5)-1))<>RESULTADOS!E5),2,IF(SIGN(VALUE(LEFT(PRONÓSTICOS!C5,FIND("-",PRONÓSTICOS!C5)-1))-VALUE(MID(PRONÓSTICOS!C5,FIND("-",PRONÓSTICOS!C5)+1,10)))=SIGN(RESULTADOS!E5-RESULTADOS!F5),1,0)))) | D4: =IF(OR(RESULTADOS!E5="",RESULTADOS!E5=0,RESULTADOS!F5=""),"—",IF(AND(VALUE(LEFT(PRONÓSTICOS!D5,FIND("-",PRONÓSTICOS!D5)-1))=RESULTADOS!E5,VALUE(MID(PRONÓSTICOS!D5,FIND("-",PRONÓSTICOS!D5)+1,10))=RESULTADOS!F5),3,IF(AND(VALUE(LEFT(PRONÓSTICOS!D5,FIND("-",PRONÓSTICOS!D5)-1))-VALUE(MID(PRONÓSTICOS!D5,FIND("-",PRONÓSTICOS!D5)+1,10))=RESULTADOS!E5-RESULTADOS!F5,VALUE(LEFT(PRONÓSTICOS!D5,FIND("-",PRONÓSTICOS!D5)-1))<>RESULTADOS!E5),2,IF(SIGN(VALUE(LEFT(PRONÓSTICOS!D5,FIND("-",PRONÓSTICOS!D5)-1))-VALUE(MID(PRONÓSTICOS!D5,FIND("-",PRONÓSTICOS!D5)+1,10)))=SIGN(RESULTADOS!E5-RESULTADOS!F5),1,0)))) | E4: =IF(OR(RESULTADOS!E5="",RESULTADOS!E5=0,RESULTADOS!F5=""),"—",IF(AND(VALUE(LEFT(PRONÓSTICOS!E5,FIND("-",PRONÓSTICOS!E5)-1))=RESULTADOS!E5,VALUE(MID(PRONÓSTICOS!E5,FIND("-",PRONÓSTICOS!E5)+1,10))=RESULTADOS!F5),3,IF(AND(VALUE(LEFT(PRONÓSTICOS!E5,FIND("-",PRONÓSTICOS!E5)-1))-VALUE(MID(PRONÓSTICOS!E5,FIND("-",PRONÓSTICOS!E5)+1,10))=RESULTADOS!E5-RESULTADOS!F5,VALUE(LEFT(PRONÓSTICOS!E5,FIND("-",PRONÓSTICOS!E5)-1))<>RESULTADOS!E5),2,IF(SIGN(VALUE(LEFT(PRONÓSTICOS!E5,FIND("-",PRONÓSTICOS!E5)-1))-VALUE(MID(PRONÓSTICOS!E5,FIND("-",PRONÓSTICOS!E5)+1,10)))=SIGN(RESULTADOS!E5-RESULTADOS!F5),1,0)))) | F4: =IF(OR(RESULTADOS!E5="",RESULTADOS!E5=0,RESULTADOS!F5=""),"—",IF(AND(VALUE(LEFT(PRONÓSTICOS!F5,FIND("-",PRONÓSTICOS!F5)-1))=RESULTADOS!E5,VALUE(MID(PRONÓSTICOS!F5,FIND("-",PRONÓSTICOS!F5)+1,10))=RESULTADOS!F5),3,IF(AND(VALUE(LEFT(PRONÓSTICOS!F5,FIND("-",PRONÓSTICOS!F5)-1))-VALUE(MID(PRONÓSTICOS!F5,FIND("-",PRONÓSTICOS!F5)+1,10))=RESULTADOS!E5-RESULTADOS!F5,VALUE(LEFT(PRONÓSTICOS!F5,FIND("-",PRONÓSTICOS!F5)-1))<>RESULTADOS!E5),2,IF(SIGN(VALUE(LEFT(PRONÓSTICOS!F5,FIND("-",PRONÓSTICOS!F5)-1))-VALUE(MID(PRONÓSTICOS!F5,FIND("-",PRONÓSTICOS!F5)+1,10)))=SIGN(RESULTADOS!E5-RESULTADOS!F5),1,0)))) | G4: =IF(OR(RESULTADOS!E5="",RESULTADOS!E5=0,RESULTADOS!F5=""),"—",IF(AND(VALUE(LEFT(PRONÓSTICOS!G5,FIND("-",PRONÓSTICOS!G5)-1))=RESULTADOS!E5,VALUE(MID(PRONÓSTICOS!G5,FIND("-",PRONÓSTICOS!G5)+1,10))=RESULTADOS!F5),3,IF(AND(VALUE(LEFT(PRONÓSTICOS!G5,FIND("-",PRONÓSTICOS!G5)-1))-VALUE(MID(PRONÓSTICOS!G5,FIND("-",PRONÓSTICOS!G5)+1,10))=RESULTADOS!E5-RESULTADOS!F5,VALUE(LEFT(PRONÓSTICOS!G5,FIND("-",PRONÓSTICOS!G5)-1))<>RESULTADOS!E5),2,IF(SIGN(VALUE(LEFT(PRONÓSTICOS!G5,FIND("-",PRONÓSTICOS!G5)-1))-VALUE(MID(PRONÓSTICOS!G5,FIND("-",PRONÓSTICOS!G5)+1,10)))=SIGN(RESULTADOS!E5-RESULTADOS!F5),1,0)))) | H4: =IF(OR(RESULTADOS!E5="",RESULTADOS!E5=0,RESULTADOS!F5=""),"—",IF(AND(VALUE(LEFT(PRONÓSTICOS!H5,FIND("-",PRONÓSTICOS!H5)-1))=RESULTADOS!E5,VALUE(MID(PRONÓSTICOS!H5,FIND("-",PRONÓSTICOS!H5)+1,10))=RESULTADOS!F5),3,IF(AND(VALUE(LEFT(PRONÓSTICOS!H5,FIND("-",PRONÓSTICOS!H5)-1))-VALUE(MID(PRONÓSTICOS!H5,FIND("-",PRONÓSTICOS!H5)+1,10))=RESULTADOS!E5-RESULTADOS!F5,VALUE(LEFT(PRONÓSTICOS!H5,FIND("-",PRONÓSTICOS!H5)-1))<>RESULTADOS!E5),2,IF(SIGN(VALUE(LEFT(PRONÓSTICOS!H5,FIND("-",PRONÓSTICOS!H5)-1))-VALUE(MID(PRONÓSTICOS!H5,FIND("-",PRONÓSTICOS!H5)+1,10)))=SIGN(RESULTADOS!E5-RESULTADOS!F5),1,0)))) | I4: =IF(OR(RESULTADOS!E5="",RESULTADOS!E5=0,RESULTADOS!F5=""),"—",IF(AND(VALUE(LEFT(PRONÓSTICOS!I5,FIND("-",PRONÓSTICOS!I5)-1))=RESULTADOS!E5,VALUE(MID(PRONÓSTICOS!I5,FIND("-",PRONÓSTICOS!I5)+1,10))=RESULTADOS!F5),3,IF(AND(VALUE(LEFT(PRONÓSTICOS!I5,FIND("-",PRONÓSTICOS!I5)-1))-VALUE(MID(PRONÓSTICOS!I5,FIND("-",PRONÓSTICOS!I5)+1,10))=RESULTADOS!E5-RESULTADOS!F5,VALUE(LEFT(PRONÓSTICOS!I5,FIND("-",PRONÓSTICOS!I5)-1))<>RESULTADOS!E5),2,IF(SIGN(VALUE(LEFT(PRONÓSTICOS!I5,FIND("-",PRONÓSTICOS!I5)-1))-VALUE(MID(PRONÓSTICOS!I5,FIND("-",PRONÓSTICOS!I5)+1,10)))=SIGN(RESULTADOS!E5-RESULTADOS!F5),1,0)))) | J4: =IF(OR(RESULTADOS!E5="",RESULTADOS!E5=0,RESULTADOS!F5=""),"—",IF(AND(VALUE(LEFT(PRONÓSTICOS!J5,FIND("-",PRONÓSTICOS!J5)-1))=RESULTADOS!E5,VALUE(MID(PRONÓSTICOS!J5,FIND("-",PRONÓSTICOS!J5)+1,10))=RESULTADOS!F5),3,IF(AND(VALUE(LEFT(PRONÓSTICOS!J5,FIND("-",PRONÓSTICOS!J5)-1))-VALUE(MID(PRONÓSTICOS!J5,FIND("-",PRONÓSTICOS!J5)+1,10))=RESULTADOS!E5-RESULTADOS!F5,VALUE(LEFT(PRONÓSTICOS!J5,FIND("-",PRONÓSTICOS!J5)-1))<>RESULTADOS!E5),2,IF(SIGN(VALUE(LEFT(PRONÓSTICOS!J5,FIND("-",PRONÓSTICOS!J5)-1))-VALUE(MID(PRONÓSTICOS!J5,FIND("-",PRONÓSTICOS!J5)+1,10)))=SIGN(RESULTADOS!E5-RESULTADOS!F5),1,0)))) | K4: =IF(OR(RESULTADOS!E5="",RESULTADOS!E5=0,RESULTADOS!F5=""),"—",IF(AND(VALUE(LEFT(PRONÓSTICOS!K5,FIND("-",PRONÓSTICOS!K5)-1))=RESULTADOS!E5,VALUE(MID(PRONÓSTICOS!K5,FIND("-",PRONÓSTICOS!K5)+1,10))=RESULTADOS!F5),3,IF(AND(VALUE(LEFT(PRONÓSTICOS!K5,FIND("-",PRONÓSTICOS!K5)-1))-VALUE(MID(PRONÓSTICOS!K5,FIND("-",PRONÓSTICOS!K5)+1,10))=RESULTADOS!E5-RESULTADOS!F5,VALUE(LEFT(PRONÓSTICOS!K5,FIND("-",PRONÓSTICOS!K5)-1))<>RESULTADOS!E5),2,IF(SIGN(VALUE(LEFT(PRONÓSTICOS!K5,FIND("-",PRONÓSTICOS!K5)-1))-VALUE(MID(PRONÓSTICOS!K5,FIND("-",PRONÓSTICOS!K5)+1,10)))=SIGN(RESULTADOS!E5-RESULTADOS!F5),1,0)))) | L4: =IF(OR(RESULTADOS!E5="",RESULTADOS!E5=0,RESULTADOS!F5=""),"—",IF(AND(VALUE(LEFT(PRONÓSTICOS!L5,FIND("-",PRONÓSTICOS!L5)-1))=RESULTADOS!E5,VALUE(MID(PRONÓSTICOS!L5,FIND("-",PRONÓSTICOS!L5)+1,10))=RESULTADOS!F5),3,IF(AND(VALUE(LEFT(PRONÓSTICOS!L5,FIND("-",PRONÓSTICOS!L5)-1))-VALUE(MID(PRONÓSTICOS!L5,FIND("-",PRONÓSTICOS!L5)+1,10))=RESULTADOS!E5-RESULTADOS!F5,VALUE(LEFT(PRONÓSTICOS!L5,FIND("-",PRONÓSTICOS!L5)-1))<>RESULTADOS!E5),2,IF(SIGN(VALUE(LEFT(PRONÓSTICOS!L5,FIND("-",PRONÓSTICOS!L5)-1))-VALUE(MID(PRONÓSTICOS!L5,FIND("-",PRONÓSTICOS!L5)+1,10)))=SIGN(RESULTADOS!E5-RESULTADOS!F5),1,0))))
A5: 3 | B5: Canadá vs Uruguay | C5: =IF(OR(RESULTADOS!E6="",RESULTADOS!E6=0,RESULTADOS!F6=""),"—",IF(AND(VALUE(LEFT(PRONÓSTICOS!C6,FIND("-",PRONÓSTICOS!C6)-1))=RESULTADOS!E6,VALUE(MID(PRONÓSTICOS!C6,FIND("-",PRONÓSTICOS!C6)+1,10))=RESULTADOS!F6),3,IF(AND(VALUE(LEFT(PRONÓSTICOS!C6,FIND("-",PRONÓSTICOS!C6)-1))-VALUE(MID(PRONÓSTICOS!C6,FIND("-",PRONÓSTICOS!C6)+1,10))=RESULTADOS!E6-RESULTADOS!F6,VALUE(LEFT(PRONÓSTICOS!C6,FIND("-",PRONÓSTICOS!C6)-1))<>RESULTADOS!E6),2,IF(SIGN(VALUE(LEFT(PRONÓSTICOS!C6,FIND("-",PRONÓSTICOS!C6)-1))-VALUE(MID(PRONÓSTICOS!C6,FIND("-",PRONÓSTICOS!C6)+1,10)))=SIGN(RESULTADOS!E6-RESULTADOS!F6),1,0)))) | D5: =IF(OR(RESULTADOS!E6="",RESULTADOS!E6=0,RESULTADOS!F6=""),"—",IF(AND(VALUE(LEFT(PRONÓSTICOS!D6,FIND("-",PRONÓSTICOS!D6)-1))=RESULTADOS!E6,VALUE(MID(PRONÓSTICOS!D6,FIND("-",PRONÓSTICOS!D6)+1,10))=RESULTADOS!F6),3,IF(AND(VALUE(LEFT(PRONÓSTICOS!D6,FIND("-",PRONÓSTICOS!D6)-1))-VALUE(MID(PRONÓSTICOS!D6,FIND("-",PRONÓSTICOS!D6)+1,10))=RESULTADOS!E6-RESULTADOS!F6,VALUE(LEFT(PRONÓSTICOS!D6,FIND("-",PRONÓSTICOS!D6)-1))<>RESULTADOS!E6),2,IF(SIGN(VALUE(LEFT(PRONÓSTICOS!D6,FIND("-",PRONÓSTICOS!D6)-1))-VALUE(MID(PRONÓSTICOS!D6,FIND("-",PRONÓSTICOS!D6)+1,10)))=SIGN(RESULTADOS!E6-RESULTADOS!F6),1,0)))) | E5: =IF(OR(RESULTADOS!E6="",RESULTADOS!E6=0,RESULTADOS!F6=""),"—",IF(AND(VALUE(LEFT(PRONÓSTICOS!E6,FIND("-",PRONÓSTICOS!E6)-1))=RESULTADOS!E6,VALUE(MID(PRONÓSTICOS!E6,FIND("-",PRONÓSTICOS!E6)+1,10))=RESULTADOS!F6),3,IF(AND(VALUE(LEFT(PRONÓSTICOS!E6,FIND("-",PRONÓSTICOS!E6)-1))-VALUE(MID(PRONÓSTICOS!E6,FIND("-",PRONÓSTICOS!E6)+1,10))=RESULTADOS!E6-RESULTADOS!F6,VALUE(LEFT(PRONÓSTICOS!E6,FIND("-",PRONÓSTICOS!E6)-1))<>RESULTADOS!E6),2,IF(SIGN(VALUE(LEFT(PRONÓSTICOS!E6,FIND("-",PRONÓSTICOS!E6)-1))-VALUE(MID(PRONÓSTICOS!E6,FIND("-",PRONÓSTICOS!E6)+1,10)))=SIGN(RESULTADOS!E6-RESULTADOS!F6),1,0)))) | F5: =IF(OR(RESULTADOS!E6="",RESULTADOS!E6=0,RESULTADOS!F6=""),"—",IF(AND(VALUE(LEFT(PRONÓSTICOS!F6,FIND("-",PRONÓSTICOS!F6)-1))=RESULTADOS!E6,VALUE(MID(PRONÓSTICOS!F6,FIND("-",PRONÓSTICOS!F6)+1,10))=RESULTADOS!F6),3,IF(AND(VALUE(LEFT(PRONÓSTICOS!F6,FIND("-",PRONÓSTICOS!F6)-1))-VALUE(MID(PRONÓSTICOS!F6,FIND("-",PRONÓSTICOS!F6)+1,10))=RESULTADOS!E6-RESULTADOS!F6,VALUE(LEFT(PRONÓSTICOS!F6,FIND("-",PRONÓSTICOS!F6)-1))<>RESULTADOS!E6),2,IF(SIGN(VALUE(LEFT(PRONÓSTICOS!F6,FIND("-",PRONÓSTICOS!F6)-1))-VALUE(MID(PRONÓSTICOS!F6,FIND("-",PRONÓSTICOS!F6)+1,10)))=SIGN(RESULTADOS!E6-RESULTADOS!F6),1,0)))) | G5: =IF(OR(RESULTADOS!E6="",RESULTADOS!E6=0,RESULTADOS!F6=""),"—",IF(AND(VALUE(LEFT(PRONÓSTICOS!G6,FIND("-",PRONÓSTICOS!G6)-1))=RESULTADOS!E6,VALUE(MID(PRONÓSTICOS!G6,FIND("-",PRONÓSTICOS!G6)+1,10))=RESULTADOS!F6),3,IF(AND(VALUE(LEFT(PRONÓSTICOS!G6,FIND("-",PRONÓSTICOS!G6)-1))-VALUE(MID(PRONÓSTICOS!G6,FIND("-",PRONÓSTICOS!G6)+1,10))=RESULTADOS!E6-RESULTADOS!F6,VALUE(LEFT(PRONÓSTICOS!G6,FIND("-",PRONÓSTICOS!G6)-1))<>RESULTADOS!E6),2,IF(SIGN(VALUE(LEFT(PRONÓSTICOS!G6,FIND("-",PRONÓSTICOS!G6)-1))-VALUE(MID(PRONÓSTICOS!G6,FIND("-",PRONÓSTICOS!G6)+1,10)))=SIGN(RESULTADOS!E6-RESULTADOS!F6),1,0)))) | H5: =IF(OR(RESULTADOS!E6="",RESULTADOS!E6=0,RESULTADOS!F6=""),"—",IF(AND(VALUE(LEFT(PRONÓSTICOS!H6,FIND("-",PRONÓSTICOS!H6)-1))=RESULTADOS!E6,VALUE(MID(PRONÓSTICOS!H6,FIND("-",PRONÓSTICOS!H6)+1,10))=RESULTADOS!F6),3,IF(AND(VALUE(LEFT(PRONÓSTICOS!H6,FIND("-",PRONÓSTICOS!H6)-1))-VALUE(MID(PRONÓSTICOS!H6,FIND("-",PRONÓSTICOS!H6)+1,10))=RESULTADOS!E6-RESULTADOS!F6,VALUE(LEFT(PRONÓSTICOS!H6,FIND("-",PRONÓSTICOS!H6)-1))<>RESULTADOS!E6),2,IF(SIGN(VALUE(LEFT(PRONÓSTICOS!H6,FIND("-",PRONÓSTICOS!H6)-1))-VALUE(MID(PRONÓSTICOS!H6,FIND("-",PRONÓSTICOS!H6)+1,10)))=SIGN(RESULTADOS!E6-RESULTADOS!F6),1,0)))) | I5: =IF(OR(RESULTADOS!E6="",RESULTADOS!E6=0,RESULTADOS!F6=""),"—",IF(AND(VALUE(LEFT(PRONÓSTICOS!I6,FIND("-",PRONÓSTICOS!I6)-1))=RESULTADOS!E6,VALUE(MID(PRONÓSTICOS!I6,FIND("-",PRONÓSTICOS!I6)+1,10))=RESULTADOS!F6),3,IF(AND(VALUE(LEFT(PRONÓSTICOS!I6,FIND("-",PRONÓSTICOS!I6)-1))-VALUE(MID(PRONÓSTICOS!I6,FIND("-",PRONÓSTICOS!I6)+1,10))=RESULTADOS!E6-RESULTADOS!F6,VALUE(LEFT(PRONÓSTICOS!I6,FIND("-",PRONÓSTICOS!I6)-1))<>RESULTADOS!E6),2,IF(SIGN(VALUE(LEFT(PRONÓSTICOS!I6,FIND("-",PRONÓSTICOS!I6)-1))-VALUE(MID(PRONÓSTICOS!I6,FIND("-",PRONÓSTICOS!I6)+1,10)))=SIGN(RESULTADOS!E6-RESULTADOS!F6),1,0)))) | J5: =IF(OR(RESULTADOS!E6="",RESULTADOS!E6=0,RESULTADOS!F6=""),"—",IF(AND(VALUE(LEFT(PRONÓSTICOS!J6,FIND("-",PRONÓSTICOS!J6)-1))=RESULTADOS!E6,VALUE(MID(PRONÓSTICOS!J6,FIND("-",PRONÓSTICOS!J6)+1,10))=RESULTADOS!F6),3,IF(AND(VALUE(LEFT(PRONÓSTICOS!J6,FIND("-",PRONÓSTICOS!J6)-1))-VALUE(MID(PRONÓSTICOS!J6,FIND("-",PRONÓSTICOS!J6)+1,10))=RESULTADOS!E6-RESULTADOS!F6,VALUE(LEFT(PRONÓSTICOS!J6,FIND("-",PRONÓSTICOS!J6)-1))<>RESULTADOS!E6),2,IF(SIGN(VALUE(LEFT(PRONÓSTICOS!J6,FIND("-",PRONÓSTICOS!J6)-1))-VALUE(MID(PRONÓSTICOS!J6,FIND("-",PRONÓSTICOS!J6)+1,10)))=SIGN(RESULTADOS!E6-RESULTADOS!F6),1,0)))) | K5: =IF(OR(RESULTADOS!E6="",RESULTADOS!E6=0,RESULTADOS!F6=""),"—",IF(AND(VALUE(LEFT(PRONÓSTICOS!K6,FIND("-",PRONÓSTICOS!K6)-1))=RESULTADOS!E6,VALUE(MID(PRONÓSTICOS!K6,FIND("-",PRONÓSTICOS!K6)+1,10))=RESULTADOS!F6),3,IF(AND(VALUE(LEFT(PRONÓSTICOS!K6,FIND("-",PRONÓSTICOS!K6)-1))-VALUE(MID(PRONÓSTICOS!K6,FIND("-",PRONÓSTICOS!K6)+1,10))=RESULTADOS!E6-RESULTADOS!F6,VALUE(LEFT(PRONÓSTICOS!K6,FIND("-",PRONÓSTICOS!K6)-1))<>RESULTADOS!E6),2,IF(SIGN(VALUE(LEFT(PRONÓSTICOS!K6,FIND("-",PRONÓSTICOS!K6)-1))-VALUE(MID(PRONÓSTICOS!K6,FIND("-",PRONÓSTICOS!K6)+1,10)))=SIGN(RESULTADOS!E6-RESULTADOS!F6),1,0)))) | L5: =IF(OR(RESULTADOS!E6="",RESULTADOS!E6=0,RESULTADOS!F6=""),"—",IF(AND(VALUE(LEFT(PRONÓSTICOS!L6,FIND("-",PRONÓSTICOS!L6)-1))=RESULTADOS!E6,VALUE(MID(PRONÓSTICOS!L6,FIND("-",PRONÓSTICOS!L6)+1,10))=RESULTADOS!F6),3,IF(AND(VALUE(LEFT(PRONÓSTICOS!L6,FIND("-",PRONÓSTICOS!L6)-1))-VALUE(MID(PRONÓSTICOS!L6,FIND("-",PRONÓSTICOS!L6)+1,10))=RESULTADOS!E6-RESULTADOS!F6,VALUE(LEFT(PRONÓSTICOS!L6,FIND("-",PRONÓSTICOS!L6)-1))<>RESULTADOS!E6),2,IF(SIGN(VALUE(LEFT(PRONÓSTICOS!L6,FIND("-",PRONÓSTICOS!L6)-1))-VALUE(MID(PRONÓSTICOS!L6,FIND("-",PRONÓSTICOS!L6)+1,10)))=SIGN(RESULTADOS!E6-RESULTADOS!F6),1,0))))
A6: 4 | B6: México vs Ecuador | C6: =IF(OR(RESULTADOS!E7="",RESULTADOS!E7=0,RESULTADOS!F7=""),"—",IF(AND(VALUE(LEFT(PRONÓSTICOS!C7,FIND("-",PRONÓSTICOS!C7)-1))=RESULTADOS!E7,VALUE(MID(PRONÓSTICOS!C7,FIND("-",PRONÓSTICOS!C7)+1,10))=RESULTADOS!F7),3,IF(AND(VALUE(LEFT(PRONÓSTICOS!C7,FIND("-",PRONÓSTICOS!C7)-1))-VALUE(MID(PRONÓSTICOS!C7,FIND("-",PRONÓSTICOS!C7)+1,10))=RESULTADOS!E7-RESULTADOS!F7,VALUE(LEFT(PRONÓSTICOS!C7,FIND("-",PRONÓSTICOS!C7)-1))<>RESULTADOS!E7),2,IF(SIGN(VALUE(LEFT(PRONÓSTICOS!C7,FIND("-",PRONÓSTICOS!C7)-1))-VALUE(MID(PRONÓSTICOS!C7,FIND("-",PRONÓSTICOS!C7)+1,10)))=SIGN(RESULTADOS!E7-RESULTADOS!F7),1,0)))) | D6: =IF(OR(RESULTADOS!E7="",RESULTADOS!E7=0,RESULTADOS!F7=""),"—",IF(AND(VALUE(LEFT(PRONÓSTICOS!D7,FIND("-",PRONÓSTICOS!D7)-1))=RESULTADOS!E7,VALUE(MID(PRONÓSTICOS!D7,FIND("-",PRONÓSTICOS!D7)+1,10))=RESULTADOS!F7),3,IF(AND(VALUE(LEFT(PRONÓSTICOS!D7,FIND("-",PRONÓSTICOS!D7)-1))-VALUE(MID(PRONÓSTICOS!D7,FIND("-",PRONÓSTICOS!D7)+1,10))=RESULTADOS!E7-RESULTADOS!F7,VALUE(LEFT(PRONÓSTICOS!D7,FIND("-",PRONÓSTICOS!D7)-1))<>RESULTADOS!E7),2,IF(SIGN(VALUE(LEFT(PRONÓSTICOS!D7,FIND("-",PRONÓSTICOS!D7)-1))-VALUE(MID(PRONÓSTICOS!D7,FIND("-",PRONÓSTICOS!D7)+1,10)))=SIGN(RESULTADOS!E7-RESULTADOS!F7),1,0)))) | E6: =IF(OR(RESULTADOS!E7="",RESULTADOS!E7=0,RESULTADOS!F7=""),"—",IF(AND(VALUE(LEFT(PRONÓSTICOS!E7,FIND("-",PRONÓSTICOS!E7)-1))=RESULTADOS!E7,VALUE(MID(PRONÓSTICOS!E7,FIND("-",PRONÓSTICOS!E7)+1,10))=RESULTADOS!F7),3,IF(AND(VALUE(LEFT(PRONÓSTICOS!E7,FIND("-",PRONÓSTICOS!E7)-1))-VALUE(MID(PRONÓSTICOS!E7,FIND("-",PRONÓSTICOS!E7)+1,10))=RESULTADOS!E7-RESULTADOS!F7,VALUE(LEFT(PRONÓSTICOS!E7,FIND("-",PRONÓSTICOS!E7)-1))<>RESULTADOS!E7),2,IF(SIGN(VALUE(LEFT(PRONÓSTICOS!E7,FIND("-",PRONÓSTICOS!E7)-1))-VALUE(MID(PRONÓSTICOS!E7,FIND("-",PRONÓSTICOS!E7)+1,10)))=SIGN(RESULTADOS!E7-RESULTADOS!F7),1,0)))) | F6: =IF(OR(RESULTADOS!E7="",RESULTADOS!E7=0,RESULTADOS!F7=""),"—",IF(AND(VALUE(LEFT(PRONÓSTICOS!F7,FIND("-",PRONÓSTICOS!F7)-1))=RESULTADOS!E7,VALUE(MID(PRONÓSTICOS!F7,FIND("-",PRONÓSTICOS!F7)+1,10))=RESULTADOS!F7),3,IF(AND(VALUE(LEFT(PRONÓSTICOS!F7,FIND("-",PRONÓSTICOS!F7)-1))-VALUE(MID(PRONÓSTICOS!F7,FIND("-",PRONÓSTICOS!F7)+1,10))=RESULTADOS!E7-RESULTADOS!F7,VALUE(LEFT(PRONÓSTICOS!F7,FIND("-",PRONÓSTICOS!F7)-1))<>RESULTADOS!E7),2,IF(SIGN(VALUE(LEFT(PRONÓSTICOS!F7,FIND("-",PRONÓSTICOS!F7)-1))-VALUE(MID(PRONÓSTICOS!F7,FIND("-",PRONÓSTICOS!F7)+1,10)))=SIGN(RESULTADOS!E7-RESULTADOS!F7),1,0)))) | G6: =IF(OR(RESULTADOS!E7="",RESULTADOS!E7=0,RESULTADOS!F7=""),"—",IF(AND(VALUE(LEFT(PRONÓSTICOS!G7,FIND("-",PRONÓSTICOS!G7)-1))=RESULTADOS!E7,VALUE(MID(PRONÓSTICOS!G7,FIND("-",PRONÓSTICOS!G7)+1,10))=RESULTADOS!F7),3,IF(AND(VALUE(LEFT(PRONÓSTICOS!G7,FIND("-",PRONÓSTICOS!G7)-1))-VALUE(MID(PRONÓSTICOS!G7,FIND("-",PRONÓSTICOS!G7)+1,10))=RESULTADOS!E7-RESULTADOS!F7,VALUE(LEFT(PRONÓSTICOS!G7,FIND("-",PRONÓSTICOS!G7)-1))<>RESULTADOS!E7),2,IF(SIGN(VALUE(LEFT(PRONÓSTICOS!G7,FIND("-",PRONÓSTICOS!G7)-1))-VALUE(MID(PRONÓSTICOS!G7,FIND("-",PRONÓSTICOS!G7)+1,10)))=SIGN(RESULTADOS!E7-RESULTADOS!F7),1,0)))) | H6: =IF(OR(RESULTADOS!E7="",RESULTADOS!E7=0,RESULTADOS!F7=""),"—",IF(AND(VALUE(LEFT(PRONÓSTICOS!H7,FIND("-",PRONÓSTICOS!H7)-1))=RESULTADOS!E7,VALUE(MID(PRONÓSTICOS!H7,FIND("-",PRONÓSTICOS!H7)+1,10))=RESULTADOS!F7),3,IF(AND(VALUE(LEFT(PRONÓSTICOS!H7,FIND("-",PRONÓSTICOS!H7)-1))-VALUE(MID(PRONÓSTICOS!H7,FIND("-",PRONÓSTICOS!H7)+1,10))=RESULTADOS!E7-RESULTADOS!F7,VALUE(LEFT(PRONÓSTICOS!H7,FIND("-",PRONÓSTICOS!H7)-1))<>RESULTADOS!E7),2,IF(SIGN(VALUE(LEFT(PRONÓSTICOS!H7,FIND("-",PRONÓSTICOS!H7)-1))-VALUE(MID(PRONÓSTICOS!H7,FIND("-",PRONÓSTICOS!H7)+1,10)))=SIGN(RESULTADOS!E7-RESULTADOS!F7),1,0)))) | I6: =IF(OR(RESULTADOS!E7="",RESULTADOS!E7=0,RESULTADOS!F7=""),"—",IF(AND(VALUE(LEFT(PRONÓSTICOS!I7,FIND("-",PRONÓSTICOS!I7)-1))=RESULTADOS!E7,VALUE(MID(PRONÓSTICOS!I7,FIND("-",PRONÓSTICOS!I7)+1,10))=RESULTADOS!F7),3,IF(AND(VALUE(LEFT(PRONÓSTICOS!I7,FIND("-",PRONÓSTICOS!I7)-1))-VALUE(MID(PRONÓSTICOS!I7,FIND("-",PRONÓSTICOS!I7)+1,10))=RESULTADOS!E7-RESULTADOS!F7,VALUE(LEFT(PRONÓSTICOS!I7,FIND("-",PRONÓSTICOS!I7)-1))<>RESULTADOS!E7),2,IF(SIGN(VALUE(LEFT(PRONÓSTICOS!I7,FIND("-",PRONÓSTICOS!I7)-1))-VALUE(MID(PRONÓSTICOS!I7,FIND("-",PRONÓSTICOS!I7)+1,10)))=SIGN(RESULTADOS!E7-RESULTADOS!F7),1,0)))) | J6: =IF(OR(RESULTADOS!E7="",RESULTADOS!E7=0,RESULTADOS!F7=""),"—",IF(AND(VALUE(LEFT(PRONÓSTICOS!J7,FIND("-",PRONÓSTICOS!J7)-1))=RESULTADOS!E7,VALUE(MID(PRONÓSTICOS!J7,FIND("-",PRONÓSTICOS!J7)+1,10))=RESULTADOS!F7),3,IF(AND(VALUE(LEFT(PRONÓSTICOS!J7,FIND("-",PRONÓSTICOS!J7)-1))-VALUE(MID(PRONÓSTICOS!J7,FIND("-",PRONÓSTICOS!J7)+1,10))=RESULTADOS!E7-RESULTADOS!F7,VALUE(LEFT(PRONÓSTICOS!J7,FIND("-",PRONÓSTICOS!J7)-1))<>RESULTADOS!E7),2,IF(SIGN(VALUE(LEFT(PRONÓSTICOS!J7,FIND("-",PRONÓSTICOS!J7)-1))-VALUE(MID(PRONÓSTICOS!J7,FIND("-",PRONÓSTICOS!J7)+1,10)))=SIGN(RESULTADOS!E7-RESULTADOS!F7),1,0)))) | K6: =IF(OR(RESULTADOS!E7="",RESULTADOS!E7=0,RESULTADOS!F7=""),"—",IF(AND(VALUE(LEFT(PRONÓSTICOS!K7,FIND("-",PRONÓSTICOS!K7)-1))=RESULTADOS!E7,VALUE(MID(PRONÓSTICOS!K7,FIND("-",PRONÓSTICOS!K7)+1,10))=RESULTADOS!F7),3,IF(AND(VALUE(LEFT(PRONÓSTICOS!K7,FIND("-",PRONÓSTICOS!K7)-1))-VALUE(MID(PRONÓSTICOS!K7,FIND("-",PRONÓSTICOS!K7)+1,10))=RESULTADOS!E7-RESULTADOS!F7,VALUE(LEFT(PRONÓSTICOS!K7,FIND("-",PRONÓSTICOS!K7)-1))<>RESULTADOS!E7),2,IF(SIGN(VALUE(LEFT(PRONÓSTICOS!K7,FIND("-",PRONÓSTICOS!K7)-1))-VALUE(MID(PRONÓSTICOS!K7,FIND("-",PRONÓSTICOS!K7)+1,10)))=SIGN(RESULTADOS!E7-RESULTADOS!F7),1,0)))) | L6: =IF(OR(RESULTADOS!E7="",RESULTADOS!E7=0,RESULTADOS!F7=""),"—",IF(AND(VALUE(LEFT(PRONÓSTICOS!L7,FIND("-",PRONÓSTICOS!L7)-1))=RESULTADOS!E7,VALUE(MID(PRONÓSTICOS!L7,FIND("-",PRONÓSTICOS!L7)+1,10))=RESULTADOS!F7),3,IF(AND(VALUE(LEFT(PRONÓSTICOS!L7,FIND("-",PRONÓSTICOS!L7)-1))-VALUE(MID(PRONÓSTICOS!L7,FIND("-",PRONÓSTICOS!L7)+1,10))=RESULTADOS!E7-RESULTADOS!F7,VALUE(LEFT(PRONÓSTICOS!L7,FIND("-",PRONÓSTICOS!L7)-1))<>RESULTADOS!E7),2,IF(SIGN(VALUE(LEFT(PRONÓSTICOS!L7,FIND("-",PRONÓSTICOS!L7)-1))-VALUE(MID(PRONÓSTICOS!L7,FIND("-",PRONÓSTICOS!L7)+1,10)))=SIGN(RESULTADOS!E7-RESULTADOS!F7),1,0))))
A7: 5 | B7: Jamaica vs México | C7: =IF(OR(RESULTADOS!E8="",RESULTADOS!E8=0,RESULTADOS!F8=""),"—",IF(AND(VALUE(LEFT(PRONÓSTICOS!C8,FIND("-",PRONÓSTICOS!C8)-1))=RESULTADOS!E8,VALUE(MID(PRONÓSTICOS!C8,FIND("-",PRONÓSTICOS!C8)+1,10))=RESULTADOS!F8),3,IF(AND(VALUE(LEFT(PRONÓSTICOS!C8,FIND("-",PRONÓSTICOS!C8)-1))-VALUE(MID(PRONÓSTICOS!C8,FIND("-",PRONÓSTICOS!C8)+1,10))=RESULTADOS!E8-RESULTADOS!F8,VALUE(LEFT(PRONÓSTICOS!C8,FIND("-",PRONÓSTICOS!C8)-1))<>RESULTADOS!E8),2,IF(SIGN(VALUE(LEFT(PRONÓSTICOS!C8,FIND("-",PRONÓSTICOS!C8)-1))-VALUE(MID(PRONÓSTICOS!C8,FIND("-",PRONÓSTICOS!C8)+1,10)))=SIGN(RESULTADOS!E8-RESULTADOS!F8),1,0)))) | D7: =IF(OR(RESULTADOS!E8="",RESULTADOS!E8=0,RESULTADOS!F8=""),"—",IF(AND(VALUE(LEFT(PRONÓSTICOS!D8,FIND("-",PRONÓSTICOS!D8)-1))=RESULTADOS!E8,VALUE(MID(PRONÓSTICOS!D8,FIND("-",PRONÓSTICOS!D8)+1,10))=RESULTADOS!F8),3,IF(AND(VALUE(LEFT(PRONÓSTICOS!D8,FIND("-",PRONÓSTICOS!D8)-1))-VALUE(MID(PRONÓSTICOS!D8,FIND("-",PRONÓSTICOS!D8)+1,10))=RESULTADOS!E8-RESULTADOS!F8,VALUE(LEFT(PRONÓSTICOS!D8,FIND("-",PRONÓSTICOS!D8)-1))<>RESULTADOS!E8),2,IF(SIGN(VALUE(LEFT(PRONÓSTICOS!D8,FIND("-",PRONÓSTICOS!D8)-1))-VALUE(MID(PRONÓSTICOS!D8,FIND("-",PRONÓSTICOS!D8)+1,10)))=SIGN(RESULTADOS!E8-RESULTADOS!F8),1,0)))) | E7: =IF(OR(RESULTADOS!E8="",RESULTADOS!E8=0,RESULTADOS!F8=""),"—",IF(AND(VALUE(LEFT(PRONÓSTICOS!E8,FIND("-",PRONÓSTICOS!E8)-1))=RESULTADOS!E8,VALUE(MID(PRONÓSTICOS!E8,FIND("-",PRONÓSTICOS!E8)+1,10))=RESULTADOS!F8),3,IF(AND(VALUE(LEFT(PRONÓSTICOS!E8,FIND("-",PRONÓSTICOS!E8)-1))-VALUE(MID(PRONÓSTICOS!E8,FIND("-",PRONÓSTICOS!E8)+1,10))=RESULTADOS!E8-RESULTADOS!F8,VALUE(LEFT(PRONÓSTICOS!E8,FIND("-",PRONÓSTICOS!E8)-1))<>RESULTADOS!E8),2,IF(SIGN(VALUE(LEFT(PRONÓSTICOS!E8,FIND("-",PRONÓSTICOS!E8)-1))-VALUE(MID(PRONÓSTICOS!E8,FIND("-",PRONÓSTICOS!E8)+1,10)))=SIGN(RESULTADOS!E8-RESULTADOS!F8),1,0)))) | F7: =IF(OR(RESULTADOS!E8="",RESULTADOS!E8=0,RESULTADOS!F8=""),"—",IF(AND(VALUE(LEFT(PRONÓSTICOS!F8,FIND("-",PRONÓSTICOS!F8)-1))=RESULTADOS!E8,VALUE(MID(PRONÓSTICOS!F8,FIND("-",PRONÓSTICOS!F8)+1,10))=RESULTADOS!F8),3,IF(AND(VALUE(LEFT(PRONÓSTICOS!F8,FIND("-",PRONÓSTICOS!F8)-1))-VALUE(MID(PRONÓSTICOS!F8,FIND("-",PRONÓSTICOS!F8)+1,10))=RESULTADOS!E8-RESULTADOS!F8,VALUE(LEFT(PRONÓSTICOS!F8,FIND("-",PRONÓSTICOS!F8)-1))<>RESULTADOS!E8),2,IF(SIGN(VALUE(LEFT(PRONÓSTICOS!F8,FIND("-",PRONÓSTICOS!F8)-1))-VALUE(MID(PRONÓSTICOS!F8,FIND("-",PRONÓSTICOS!F8)+1,10)))=SIGN(RESULTADOS!E8-RESULTADOS!F8),1,0)))) | G7: =IF(OR(RESULTADOS!E8="",RESULTADOS!E8=0,RESULTADOS!F8=""),"—",IF(AND(VALUE(LEFT(PRONÓSTICOS!G8,FIND("-",PRONÓSTICOS!G8)-1))=RESULTADOS!E8,VALUE(MID(PRONÓSTICOS!G8,FIND("-",PRONÓSTICOS!G8)+1,10))=RESULTADOS!F8),3,IF(AND(VALUE(LEFT(PRONÓSTICOS!G8,FIND("-",PRONÓSTICOS!G8)-1))-VALUE(MID(PRONÓSTICOS!G8,FIND("-",PRONÓSTICOS!G8)+1,10))=RESULTADOS!E8-RESULTADOS!F8,VALUE(LEFT(PRONÓSTICOS!G8,FIND("-",PRONÓSTICOS!G8)-1))<>RESULTADOS!E8),2,IF(SIGN(VALUE(LEFT(PRONÓSTICOS!G8,FIND("-",PRONÓSTICOS!G8)-1))-VALUE(MID(PRONÓSTICOS!G8,FIND("-",PRONÓSTICOS!G8)+1,10)))=SIGN(RESULTADOS!E8-RESULTADOS!F8),1,0)))) | H7: =IF(OR(RESULTADOS!E8="",RESULTADOS!E8=0,RESULTADOS!F8=""),"—",IF(AND(VALUE(LEFT(PRONÓSTICOS!H8,FIND("-",PRONÓSTICOS!H8)-1))=RESULTADOS!E8,VALUE(MID(PRONÓSTICOS!H8,FIND("-",PRONÓSTICOS!H8)+1,10))=RESULTADOS!F8),3,IF(AND(VALUE(LEFT(PRONÓSTICOS!H8,FIND("-",PRONÓSTICOS!H8)-1))-VALUE(MID(PRONÓSTICOS!H8,FIND("-",PRONÓSTICOS!H8)+1,10))=RESULTADOS!E8-RESULTADOS!F8,VALUE(LEFT(PRONÓSTICOS!H8,FIND("-",PRONÓSTICOS!H8)-1))<>RESULTADOS!E8),2,IF(SIGN(VALUE(LEFT(PRONÓSTICOS!H8,FIND("-",PRONÓSTICOS!H8)-1))-VALUE(MID(PRONÓSTICOS!H8,FIND("-",PRONÓSTICOS!H8)+1,10)))=SIGN(RESULTADOS!E8-RESULTADOS!F8),1,0)))) | I7: =IF(OR(RESULTADOS!E8="",RESULTADOS!E8=0,RESULTADOS!F8=""),"—",IF(AND(VALUE(LEFT(PRONÓSTICOS!I8,FIND("-",PRONÓSTICOS!I8)-1))=RESULTADOS!E8,VALUE(MID(PRONÓSTICOS!I8,FIND("-",PRONÓSTICOS!I8)+1,10))=RESULTADOS!F8),3,IF(AND(VALUE(LEFT(PRONÓSTICOS!I8,FIND("-",PRONÓSTICOS!I8)-1))-VALUE(MID(PRONÓSTICOS!I8,FIND("-",PRONÓSTICOS!I8)+1,10))=RESULTADOS!E8-RESULTADOS!F8,VALUE(LEFT(PRONÓSTICOS!I8,FIND("-",PRONÓSTICOS!I8)-1))<>RESULTADOS!E8),2,IF(SIGN(VALUE(LEFT(PRONÓSTICOS!I8,FIND("-",PRONÓSTICOS!I8)-1))-VALUE(MID(PRONÓSTICOS!I8,FIND("-",PRONÓSTICOS!I8)+1,10)))=SIGN(RESULTADOS!E8-RESULTADOS!F8),1,0)))) | J7: =IF(OR(RESULTADOS!E8="",RESULTADOS!E8=0,RESULTADOS!F8=""),"—",IF(AND(VALUE(LEFT(PRONÓSTICOS!J8,FIND("-",PRONÓSTICOS!J8)-1))=RESULTADOS!E8,VALUE(MID(PRONÓSTICOS!J8,FIND("-",PRONÓSTICOS!J8)+1,10))=RESULTADOS!F8),3,IF(AND(VALUE(LEFT(PRONÓSTICOS!J8,FIND("-",PRONÓSTICOS!J8)-1))-VALUE(MID(PRONÓSTICOS!J8,FIND("-",PRONÓSTICOS!J8)+1,10))=RESULTADOS!E8-RESULTADOS!F8,VALUE(LEFT(PRONÓSTICOS!J8,FIND("-",PRONÓSTICOS!J8)-1))<>RESULTADOS!E8),2,IF(SIGN(VALUE(LEFT(PRONÓSTICOS!J8,FIND("-",PRONÓSTICOS!J8)-1))-VALUE(MID(PRONÓSTICOS!J8,FIND("-",PRONÓSTICOS!J8)+1,10)))=SIGN(RESULTADOS!E8-RESULTADOS!F8),1,0)))) | K7: =IF(OR(RESULTADOS!E8="",RESULTADOS!E8=0,RESULTADOS!F8=""),"—",IF(AND(VALUE(LEFT(PRONÓSTICOS!K8,FIND("-",PRONÓSTICOS!K8)-1))=RESULTADOS!E8,VALUE(MID(PRONÓSTICOS!K8,FIND("-",PRONÓSTICOS!K8)+1,10))=RESULTADOS!F8),3,IF(AND(VALUE(LEFT(PRONÓSTICOS!K8,FIND("-",PRONÓSTICOS!K8)-1))-VALUE(MID(PRONÓSTICOS!K8,FIND("-",PRONÓSTICOS!K8)+1,10))=RESULTADOS!E8-RESULTADOS!F8,VALUE(LEFT(PRONÓSTICOS!K8,FIND("-",PRONÓSTICOS!K8)-1))<>RESULTADOS!E8),2,IF(SIGN(VALUE(LEFT(PRONÓSTICOS!K8,FIND("-",PRONÓSTICOS!K8)-1))-VALUE(MID(PRONÓSTICOS!K8,FIND("-",PRONÓSTICOS!K8)+1,10)))=SIGN(RESULTADOS!E8-RESULTADOS!F8),1,0)))) | L7: =IF(OR(RESULTADOS!E8="",RESULTADOS!E8=0,RESULTADOS!F8=""),"—",IF(AND(VALUE(LEFT(PRONÓSTICOS!L8,FIND("-",PRONÓSTICOS!L8)-1))=RESULTADOS!E8,VALUE(MID(PRONÓSTICOS!L8,FIND("-",PRONÓSTICOS!L8)+1,10))=RESULTADOS!F8),3,IF(AND(VALUE(LEFT(PRONÓSTICOS!L8,FIND("-",PRONÓSTICOS!L8)-1))-VALUE(MID(PRONÓSTICOS!L8,FIND("-",PRONÓSTICOS!L8)+1,10))=RESULTADOS!E8-RESULTADOS!F8,VALUE(LEFT(PRONÓSTICOS!L8,FIND("-",PRONÓSTICOS!L8)-1))<>RESULTADOS!E8),2,IF(SIGN(VALUE(LEFT(PRONÓSTICOS!L8,FIND("-",PRONÓSTICOS!L8)-1))-VALUE(MID(PRONÓSTICOS!L8,FIND("-",PRONÓSTICOS!L8)+1,10)))=SIGN(RESULTADOS!E8-RESULTADOS!F8),1,0))))
A8: 6 | B8: Ecuador vs Jamaica | C8: =IF(OR(RESULTADOS!E9="",RESULTADOS!E9=0,RESULTADOS!F9=""),"—",IF(AND(VALUE(LEFT(PRONÓSTICOS!C9,FIND("-",PRONÓSTICOS!C9)-1))=RESULTADOS!E9,VALUE(MID(PRONÓSTICOS!C9,FIND("-",PRONÓSTICOS!C9)+1,10))=RESULTADOS!F9),3,IF(AND(VALUE(LEFT(PRONÓSTICOS!C9,FIND("-",PRONÓSTICOS!C9)-1))-VALUE(MID(PRONÓSTICOS!C9,FIND("-",PRONÓSTICOS!C9)+1,10))=RESULTADOS!E9-RESULTADOS!F9,VALUE(LEFT(PRONÓSTICOS!C9,FIND("-",PRONÓSTICOS!C9)-1))<>RESULTADOS!E9),2,IF(SIGN(VALUE(LEFT(PRONÓSTICOS!C9,FIND("-",PRONÓSTICOS!C9)-1))-VALUE(MID(PRONÓSTICOS!C9,FIND("-",PRONÓSTICOS!C9)+1,10)))=SIGN(RESULTADOS!E9-RESULTADOS!F9),1,0)))) | D8: =IF(OR(RESULTADOS!E9="",RESULTADOS!E9=0,RESULTADOS!F9=""),"—",IF(AND(VALUE(LEFT(PRONÓSTICOS!D9,FIND("-",PRONÓSTICOS!D9)-1))=RESULTADOS!E9,VALUE(MID(PRONÓSTICOS!D9,FIND("-",PRONÓSTICOS!D9)+1,10))=RESULTADOS!F9),3,IF(AND(VALUE(LEFT(PRONÓSTICOS!D9,FIND("-",PRONÓSTICOS!D9)-1))-VALUE(MID(PRONÓSTICOS!D9,FIND("-",PRONÓSTICOS!D9)+1,10))=RESULTADOS!E9-RESULTADOS!F9,VALUE(LEFT(PRONÓSTICOS!D9,FIND("-",PRONÓSTICOS!D9)-1))<>RESULTADOS!E9),2,IF(SIGN(VALUE(LEFT(PRONÓSTICOS!D9,FIND("-",PRONÓSTICOS!D9)-1))-VALUE(MID(PRONÓSTICOS!D9,FIND("-",PRONÓSTICOS!D9)+1,10)))=SIGN(RESULTADOS!E9-RESULTADOS!F9),1,0)))) | E8: =IF(OR(RESULTADOS!E9="",RESULTADOS!E9=0,RESULTADOS!F9=""),"—",IF(AND(VALUE(LEFT(PRONÓSTICOS!E9,FIND("-",PRONÓSTICOS!E9)-1))=RESULTADOS!E9,VALUE(MID(PRONÓSTICOS!E9,FIND("-",PRONÓSTICOS!E9)+1,10))=RESULTADOS!F9),3,IF(AND(VALUE(LEFT(PRONÓSTICOS!E9,FIND("-",PRONÓSTICOS!E9)-1))-VALUE(MID(PRONÓSTICOS!E9,FIND("-",PRONÓSTICOS!E9)+1,10))=RESULTADOS!E9-RESULTADOS!F9,VALUE(LEFT(PRONÓSTICOS!E9,FIND("-",PRONÓSTICOS!E9)-1))<>RESULTADOS!E9),2,IF(SIGN(VALUE(LEFT(PRONÓSTICOS!E9,FIND("-",PRONÓSTICOS!E9)-1))-VALUE(MID(PRONÓSTICOS!E9,FIND("-",PRONÓSTICOS!E9)+1,10)))=SIGN(RESULTADOS!E9-RESULTADOS!F9),1,0)))) | F8: =IF(OR(RESULTADOS!E9="",RESULTADOS!E9=0,RESULTADOS!F9=""),"—",IF(AND(VALUE(LEFT(PRONÓSTICOS!F9,FIND("-",PRONÓSTICOS!F9)-1))=RESULTADOS!E9,VALUE(MID(PRONÓSTICOS!F9,FIND("-",PRONÓSTICOS!F9)+1,10))=RESULTADOS!F9),3,IF(AND(VALUE(LEFT(PRONÓSTICOS!F9,FIND("-",PRONÓSTICOS!F9)-1))-VALUE(MID(PRONÓSTICOS!F9,FIND("-",PRONÓSTICOS!F9)+1,10))=RESULTADOS!E9-RESULTADOS!F9,VALUE(LEFT(PRONÓSTICOS!F9,FIND("-",PRONÓSTICOS!F9)-1))<>RESULTADOS!E9),2,IF(SIGN(VALUE(LEFT(PRONÓSTICOS!F9,FIND("-",PRONÓSTICOS!F9)-1))-VALUE(MID(PRONÓSTICOS!F9,FIND("-",PRONÓSTICOS!F9)+1,10)))=SIGN(RESULTADOS!E9-RESULTADOS!F9),1,0)))) | G8: =IF(OR(RESULTADOS!E9="",RESULTADOS!E9=0,RESULTADOS!F9=""),"—",IF(AND(VALUE(LEFT(PRONÓSTICOS!G9,FIND("-",PRONÓSTICOS!G9)-1))=RESULTADOS!E9,VALUE(MID(PRONÓSTICOS!G9,FIND("-",PRONÓSTICOS!G9)+1,10))=RESULTADOS!F9),3,IF(AND(VALUE(LEFT(PRONÓSTICOS!G9,FIND("-",PRONÓSTICOS!G9)-1))-VALUE(MID(PRONÓSTICOS!G9,FIND("-",PRONÓSTICOS!G9)+1,10))=RESULTADOS!E9-RESULTADOS!F9,VALUE(LEFT(PRONÓSTICOS!G9,FIND("-",PRONÓSTICOS!G9)-1))<>RESULTADOS!E9),2,IF(SIGN(VALUE(LEFT(PRONÓSTICOS!G9,FIND("-",PRONÓSTICOS!G9)-1))-VALUE(MID(PRONÓSTICOS!G9,FIND("-",PRONÓSTICOS!G9)+1,10)))=SIGN(RESULTADOS!E9-RESULTADOS!F9),1,0)))) | H8: =IF(OR(RESULTADOS!E9="",RESULTADOS!E9=0,RESULTADOS!F9=""),"—",IF(AND(VALUE(LEFT(PRONÓSTICOS!H9,FIND("-",PRONÓSTICOS!H9)-1))=RESULTADOS!E9,VALUE(MID(PRONÓSTICOS!H9,FIND("-",PRONÓSTICOS!H9)+1,10))=RESULTADOS!F9),3,IF(AND(VALUE(LEFT(PRONÓSTICOS!H9,FIND("-",PRONÓSTICOS!H9)-1))-VALUE(MID(PRONÓSTICOS!H9,FIND("-",PRONÓSTICOS!H9)+1,10))=RESULTADOS!E9-RESULTADOS!F9,VALUE(LEFT(PRONÓSTICOS!H9,FIND("-",PRONÓSTICOS!H9)-1))<>RESULTADOS!E9),2,IF(SIGN(VALUE(LEFT(PRONÓSTICOS!H9,FIND("-",PRONÓSTICOS!H9)-1))-VALUE(MID(PRONÓSTICOS!H9,FIND("-",PRONÓSTICOS!H9)+1,10)))=SIGN(RESULTADOS!E9-RESULTADOS!F9),1,0)))) | I8: =IF(OR(RESULTADOS!E9="",RESULTADOS!E9=0,RESULTADOS!F9=""),"—",IF(AND(VALUE(LEFT(PRONÓSTICOS!I9,FIND("-",PRONÓSTICOS!I9)-1))=RESULTADOS!E9,VALUE(MID(PRONÓSTICOS!I9,FIND("-",PRONÓSTICOS!I9)+1,10))=RESULTADOS!F9),3,IF(AND(VALUE(LEFT(PRONÓSTICOS!I9,FIND("-",PRONÓSTICOS!I9)-1))-VALUE(MID(PRONÓSTICOS!I9,FIND("-",PRONÓSTICOS!I9)+1,10))=RESULTADOS!E9-RESULTADOS!F9,VALUE(LEFT(PRONÓSTICOS!I9,FIND("-",PRONÓSTICOS!I9)-1))<>RESULTADOS!E9),2,IF(SIGN(VALUE(LEFT(PRONÓSTICOS!I9,FIND("-",PRONÓSTICOS!I9)-1))-VALUE(MID(PRONÓSTICOS!I9,FIND("-",PRONÓSTICOS!I9)+1,10)))=SIGN(RESULTADOS!E9-RESULTADOS!F9),1,0)))) | J8: =IF(OR(RESULTADOS!E9="",RESULTADOS!E9=0,RESULTADOS!F9=""),"—",IF(AND(VALUE(LEFT(PRONÓSTICOS!J9,FIND("-",PRONÓSTICOS!J9)-1))=RESULTADOS!E9,VALUE(MID(PRONÓSTICOS!J9,FIND("-",PRONÓSTICOS!J9)+1,10))=RESULTADOS!F9),3,IF(AND(VALUE(LEFT(PRONÓSTICOS!J9,FIND("-",PRONÓSTICOS!J9)-1))-VALUE(MID(PRONÓSTICOS!J9,FIND("-",PRONÓSTICOS!J9)+1,10))=RESULTADOS!E9-RESULTADOS!F9,VALUE(LEFT(PRONÓSTICOS!J9,FIND("-",PRONÓSTICOS!J9)-1))<>RESULTADOS!E9),2,IF(SIGN(VALUE(LEFT(PRONÓSTICOS!J9,FIND("-",PRONÓSTICOS!J9)-1))-VALUE(MID(PRONÓSTICOS!J9,FIND("-",PRONÓSTICOS!J9)+1,10)))=SIGN(RESULTADOS!E9-RESULTADOS!F9),1,0)))) | K8: =IF(OR(RESULTADOS!E9="",RESULTADOS!E9=0,RESULTADOS!F9=""),"—",IF(AND(VALUE(LEFT(PRONÓSTICOS!K9,FIND("-",PRONÓSTICOS!K9)-1))=RESULTADOS!E9,VALUE(MID(PRONÓSTICOS!K9,FIND("-",PRONÓSTICOS!K9)+1,10))=RESULTADOS!F9),3,IF(AND(VALUE(LEFT(PRONÓSTICOS!K9,FIND("-",PRONÓSTICOS!K9)-1))-VALUE(MID(PRONÓSTICOS!K9,FIND("-",PRONÓSTICOS!K9)+1,10))=RESULTADOS!E9-RESULTADOS!F9,VALUE(LEFT(PRONÓSTICOS!K9,FIND("-",PRONÓSTICOS!K9)-1))<>RESULTADOS!E9),2,IF(SIGN(VALUE(LEFT(PRONÓSTICOS!K9,FIND("-",PRONÓSTICOS!K9)-1))-VALUE(MID(PRONÓSTICOS!K9,FIND("-",PRONÓSTICOS!K9)+1,10)))=SIGN(RESULTADOS!E9-RESULTADOS!F9),1,0)))) | L8: =IF(OR(RESULTADOS!E9="",RESULTADOS!E9=0,RESULTADOS!F9=""),"—",IF(AND(VALUE(LEFT(PRONÓSTICOS!L9,FIND("-",PRONÓSTICOS!L9)-1))=RESULTADOS!E9,VALUE(MID(PRONÓSTICOS!L9,FIND("-",PRONÓSTICOS!L9)+1,10))=RESULTADOS!F9),3,IF(AND(VALUE(LEFT(PRONÓSTICOS!L9,FIND("-",PRONÓSTICOS!L9)-1))-VALUE(MID(PRONÓSTICOS!L9,FIND("-",PRONÓSTICOS!L9)+1,10))=RESULTADOS!E9-RESULTADOS!F9,VALUE(LEFT(PRONÓSTICOS!L9,FIND("-",PRONÓSTICOS!L9)-1))<>RESULTADOS!E9),2,IF(SIGN(VALUE(LEFT(PRONÓSTICOS!L9,FIND("-",PRONÓSTICOS!L9)-1))-VALUE(MID(PRONÓSTICOS!L9,FIND("-",PRONÓSTICOS!L9)+1,10)))=SIGN(RESULTADOS!E9-RESULTADOS!F9),1,0))))
A9: 7 | B9: Argentina vs Chile | C9: =IF(OR(RESULTADOS!E10="",RESULTADOS!E10=0,RESULTADOS!F10=""),"—",IF(AND(VALUE(LEFT(PRONÓSTICOS!C10,FIND("-",PRONÓSTICOS!C10)-1))=RESULTADOS!E10,VALUE(MID(PRONÓSTICOS!C10,FIND("-",PRONÓSTICOS!C10)+1,10))=RESULTADOS!F10),3,IF(AND(VALUE(LEFT(PRONÓSTICOS!C10,FIND("-",PRONÓSTICOS!C10)-1))-VALUE(MID(PRONÓSTICOS!C10,FIND("-",PRONÓSTICOS!C10)+1,10))=RESULTADOS!E10-RESULTADOS!F10,VALUE(LEFT(PRONÓSTICOS!C10,FIND("-",PRONÓSTICOS!C10)-1))<>RESULTADOS!E10),2,IF(SIGN(VALUE(LEFT(PRONÓSTICOS!C10,FIND("-",PRONÓSTICOS!C10)-1))-VALUE(MID(PRONÓSTICOS!C10,FIND("-",PRONÓSTICOS!C10)+1,10)))=SIGN(RESULTADOS!E10-RESULTADOS!F10),1,0)))) | D9: =IF(OR(RESULTADOS!E10="",RESULTADOS!E10=0,RESULTADOS!F10=""),"—",IF(AND(VALUE(LEFT(PRONÓSTICOS!D10,FIND("-",PRONÓSTICOS!D10)-1))=RESULTADOS!E10,VALUE(MID(PRONÓSTICOS!D10,FIND("-",PRONÓSTICOS!D10)+1,10))=RESULTADOS!F10),3,IF(AND(VALUE(LEFT(PRONÓSTICOS!D10,FIND("-",PRONÓSTICOS!D10)-1))-VALUE(MID(PRONÓSTICOS!D10,FIND("-",PRONÓSTICOS!D10)+1,10))=RESULTADOS!E10-RESULTADOS!F10,VALUE(LEFT(PRONÓSTICOS!D10,FIND("-",PRONÓSTICOS!D10)-1))<>RESULTADOS!E10),2,IF(SIGN(VALUE(LEFT(PRONÓSTICOS!D10,FIND("-",PRONÓSTICOS!D10)-1))-VALUE(MID(PRONÓSTICOS!D10,FIND("-",PRONÓSTICOS!D10)+1,10)))=SIGN(RESULTADOS!E10-RESULTADOS!F10),1,0)))) | E9: =IF(OR(RESULTADOS!E10="",RESULTADOS!E10=0,RESULTADOS!F10=""),"—",IF(AND(VALUE(LEFT(PRONÓSTICOS!E10,FIND("-",PRONÓSTICOS!E10)-1))=RESULTADOS!E10,VALUE(MID(PRONÓSTICOS!E10,FIND("-",PRONÓSTICOS!E10)+1,10))=RESULTADOS!F10),3,IF(AND(VALUE(LEFT(PRONÓSTICOS!E10,FIND("-",PRONÓSTICOS!E10)-1))-VALUE(MID(PRONÓSTICOS!E10,FIND("-",PRONÓSTICOS!E10)+1,10))=RESULTADOS!E10-RESULTADOS!F10,VALUE(LEFT(PRONÓSTICOS!E10,FIND("-",PRONÓSTICOS!E10)-1))<>RESULTADOS!E10),2,IF(SIGN(VALUE(LEFT(PRONÓSTICOS!E10,FIND("-",PRONÓSTICOS!E10)-1))-VALUE(MID(PRONÓSTICOS!E10,FIND("-",PRONÓSTICOS!E10)+1,10)))=SIGN(RESULTADOS!E10-RESULTADOS!F10),1,0)))) | F9: =IF(OR(RESULTADOS!E10="",RESULTADOS!E10=0,RESULTADOS!F10=""),"—",IF(AND(VALUE(LEFT(PRONÓSTICOS!F10,FIND("-",PRONÓSTICOS!F10)-1))=RESULTADOS!E10,VALUE(MID(PRONÓSTICOS!F10,FIND("-",PRONÓSTICOS!F10)+1,10))=RESULTADOS!F10),3,IF(AND(VALUE(LEFT(PRONÓSTICOS!F10,FIND("-",PRONÓSTICOS!F10)-1))-VALUE(MID(PRONÓSTICOS!F10,FIND("-",PRONÓSTICOS!F10)+1,10))=RESULTADOS!E10-RESULTADOS!F10,VALUE(LEFT(PRONÓSTICOS!F10,FIND("-",PRONÓSTICOS!F10)-1))<>RESULTADOS!E10),2,IF(SIGN(VALUE(LEFT(PRONÓSTICOS!F10,FIND("-",PRONÓSTICOS!F10)-1))-VALUE(MID(PRONÓSTICOS!F10,FIND("-",PRONÓSTICOS!F10)+1,10)))=SIGN(RESULTADOS!E10-RESULTADOS!F10),1,0)))) | G9: =IF(OR(RESULTADOS!E10="",RESULTADOS!E10=0,RESULTADOS!F10=""),"—",IF(AND(VALUE(LEFT(PRONÓSTICOS!G10,FIND("-",PRONÓSTICOS!G10)-1))=RESULTADOS!E10,VALUE(MID(PRONÓSTICOS!G10,FIND("-",PRONÓSTICOS!G10)+1,10))=RESULTADOS!F10),3,IF(AND(VALUE(LEFT(PRONÓSTICOS!G10,FIND("-",PRONÓSTICOS!G10)-1))-VALUE(MID(PRONÓSTICOS!G10,FIND("-",PRONÓSTICOS!G10)+1,10))=RESULTADOS!E10-RESULTADOS!F10,VALUE(LEFT(PRONÓSTICOS!G10,FIND("-",PRONÓSTICOS!G10)-1))<>RESULTADOS!E10),2,IF(SIGN(VALUE(LEFT(PRONÓSTICOS!G10,FIND("-",PRONÓSTICOS!G10)-1))-VALUE(MID(PRONÓSTICOS!G10,FIND("-",PRONÓSTICOS!G10)+1,10)))=SIGN(RESULTADOS!E10-RESULTADOS!F10),1,0)))) | H9: =IF(OR(RESULTADOS!E10="",RESULTADOS!E10=0,RESULTADOS!F10=""),"—",IF(AND(VALUE(LEFT(PRONÓSTICOS!H10,FIND("-",PRONÓSTICOS!H10)-1))=RESULTADOS!E10,VALUE(MID(PRONÓSTICOS!H10,FIND("-",PRONÓSTICOS!H10)+1,10))=RESULTADOS!F10),3,IF(AND(VALUE(LEFT(PRONÓSTICOS!H10,FIND("-",PRONÓSTICOS!H10)-1))-VALUE(MID(PRONÓSTICOS!H10,FIND("-",PRONÓSTICOS!H10)+1,10))=RESULTADOS!E10-RESULTADOS!F10,VALUE(LEFT(PRONÓSTICOS!H10,FIND("-",PRONÓSTICOS!H10)-1))<>RESULTADOS!E10),2,IF(SIGN(VALUE(LEFT(PRONÓSTICOS!H10,FIND("-",PRONÓSTICOS!H10)-1))-VALUE(MID(PRONÓSTICOS!H10,FIND("-",PRONÓSTICOS!H10)+1,10)))=SIGN(RESULTADOS!E10-RESULTADOS!F10),1,0)))) | I9: =IF(OR(RESULTADOS!E10="",RESULTADOS!E10=0,RESULTADOS!F10=""),"—",IF(AND(VALUE(LEFT(PRONÓSTICOS!I10,FIND("-",PRONÓSTICOS!I10)-1))=RESULTADOS!E10,VALUE(MID(PRONÓSTICOS!I10,FIND("-",PRONÓSTICOS!I10)+1,10))=RESULTADOS!F10),3,IF(AND(VALUE(LEFT(PRONÓSTICOS!I10,FIND("-",PRONÓSTICOS!I10)-1))-VALUE(MID(PRONÓSTICOS!I10,FIND("-",PRONÓSTICOS!I10)+1,10))=RESULTADOS!E10-RESULTADOS!F10,VALUE(LEFT(PRONÓSTICOS!I10,FIND("-",PRONÓSTICOS!I10)-1))<>RESULTADOS!E10),2,IF(SIGN(VALUE(LEFT(PRONÓSTICOS!I10,FIND("-",PRONÓSTICOS!I10)-1))-VALUE(MID(PRONÓSTICOS!I10,FIND("-",PRONÓSTICOS!I10)+1,10)))=SIGN(RESULTADOS!E10-RESULTADOS!F10),1,0)))) | J9: =IF(OR(RESULTADOS!E10="",RESULTADOS!E10=0,RESULTADOS!F10=""),"—",IF(AND(VALUE(LEFT(PRONÓSTICOS!J10,FIND("-",PRONÓSTICOS!J10)-1))=RESULTADOS!E10,VALUE(MID(PRONÓSTICOS!J10,FIND("-",PRONÓSTICOS!J10)+1,10))=RESULTADOS!F10),3,IF(AND(VALUE(LEFT(PRONÓSTICOS!J10,FIND("-",PRONÓSTICOS!J10)-1))-VALUE(MID(PRONÓSTICOS!J10,FIND("-",PRONÓSTICOS!J10)+1,10))=RESULTADOS!E10-RESULTADOS!F10,VALUE(LEFT(PRONÓSTICOS!J10,FIND("-",PRONÓSTICOS!J10)-1))<>RESULTADOS!E10),2,IF(SIGN(VALUE(LEFT(PRONÓSTICOS!J10,FIND("-",PRONÓSTICOS!J10)-1))-VALUE(MID(PRONÓSTICOS!J10,FIND("-",PRONÓSTICOS!J10)+1,10)))=SIGN(RESULTADOS!E10-RESULTADOS!F10),1,0)))) | K9: =IF(OR(RESULTADOS!E10="",RESULTADOS!E10=0,RESULTADOS!F10=""),"—",IF(AND(VALUE(LEFT(PRONÓSTICOS!K10,FIND("-",PRONÓSTICOS!K10)-1))=RESULTADOS!E10,VALUE(MID(PRONÓSTICOS!K10,FIND("-",PRONÓSTICOS!K10)+1,10))=RESULTADOS!F10),3,IF(AND(VALUE(LEFT(PRONÓSTICOS!K10,FIND("-",PRONÓSTICOS!K10)-1))-VALUE(MID(PRONÓSTICOS!K10,FIND("-",PRONÓSTICOS!K10)+1,10))=RESULTADOS!E10-RESULTADOS!F10,VALUE(LEFT(PRONÓSTICOS!K10,FIND("-",PRONÓSTICOS!K10)-1))<>RESULTADOS!E10),2,IF(SIGN(VALUE(LEFT(PRONÓSTICOS!K10,FIND("-",PRONÓSTICOS!K10)-1))-VALUE(MID(PRONÓSTICOS!K10,FIND("-",PRONÓSTICOS!K10)+1,10)))=SIGN(RESULTADOS!E10-RESULTADOS!F10),1,0)))) | L9: =IF(OR(RESULTADOS!E10="",RESULTADOS!E10=0,RESULTADOS!F10=""),"—",IF(AND(VALUE(LEFT(PRONÓSTICOS!L10,FIND("-",PRONÓSTICOS!L10)-1))=RESULTADOS!E10,VALUE(MID(PRONÓSTICOS!L10,FIND("-",PRONÓSTICOS!L10)+1,10))=RESULTADOS!F10),3,IF(AND(VALUE(LEFT(PRONÓSTICOS!L10,FIND("-",PRONÓSTICOS!L10)-1))-VALUE(MID(PRONÓSTICOS!L10,FIND("-",PRONÓSTICOS!L10)+1,10))=RESULTADOS!E10-RESULTADOS!F10,VALUE(LEFT(PRONÓSTICOS!L10,FIND("-",PRONÓSTICOS!L10)-1))<>RESULTADOS!E10),2,IF(SIGN(VALUE(LEFT(PRONÓSTICOS!L10,FIND("-",PRONÓSTICOS!L10)-1))-VALUE(MID(PRONÓSTICOS!L10,FIND("-",PRONÓSTICOS!L10)+1,10)))=SIGN(RESULTADOS!E10-RESULTADOS!F10),1,0))))
A10: 8 | B10: Albania vs Argentina | C10: =IF(OR(RESULTADOS!E11="",RESULTADOS!E11=0,RESULTADOS!F11=""),"—",IF(AND(VALUE(LEFT(PRONÓSTICOS!C11,FIND("-",PRONÓSTICOS!C11)-1))=RESULTADOS!E11,VALUE(MID(PRONÓSTICOS!C11,FIND("-",PRONÓSTICOS!C11)+1,10))=RESULTADOS!F11),3,IF(AND(VALUE(LEFT(PRONÓSTICOS!C11,FIND("-",PRONÓSTICOS!C11)-1))-VALUE(MID(PRONÓSTICOS!C11,FIND("-",PRONÓSTICOS!C11)+1,10))=RESULTADOS!E11-RESULTADOS!F11,VALUE(LEFT(PRONÓSTICOS!C11,FIND("-",PRONÓSTICOS!C11)-1))<>RESULTADOS!E11),2,IF(SIGN(VALUE(LEFT(PRONÓSTICOS!C11,FIND("-",PRONÓSTICOS!C11)-1))-VALUE(MID(PRONÓSTICOS!C11,FIND("-",PRONÓSTICOS!C11)+1,10)))=SIGN(RESULTADOS!E11-RESULTADOS!F11),1,0)))) | D10: =IF(OR(RESULTADOS!E11="",RESULTADOS!E11=0,RESULTADOS!F11=""),"—",IF(AND(VALUE(LEFT(PRONÓSTICOS!D11,FIND("-",PRONÓSTICOS!D11)-1))=RESULTADOS!E11,VALUE(MID(PRONÓSTICOS!D11,FIND("-",PRONÓSTICOS!D11)+1,10))=RESULTADOS!F11),3,IF(AND(VALUE(LEFT(PRONÓSTICOS!D11,FIND("-",PRONÓSTICOS!D11)-1))-VALUE(MID(PRONÓSTICOS!D11,FIND("-",PRONÓSTICOS!D11)+1,10))=RESULTADOS!E11-RESULTADOS!F11,VALUE(LEFT(PRONÓSTICOS!D11,FIND("-",PRONÓSTICOS!D11)-1))<>RESULTADOS!E11),2,IF(SIGN(VALUE(LEFT(PRONÓSTICOS!D11,FIND("-",PRONÓSTICOS!D11)-1))-VALUE(MID(PRONÓSTICOS!D11,FIND("-",PRONÓSTICOS!D11)+1,10)))=SIGN(RESULTADOS!E11-RESULTADOS!F11),1,0)))) | E10: =IF(OR(RESULTADOS!E11="",RESULTADOS!E11=0,RESULTADOS!F11=""),"—",IF(AND(VALUE(LEFT(PRONÓSTICOS!E11,FIND("-",PRONÓSTICOS!E11)-1))=RESULTADOS!E11,VALUE(MID(PRONÓSTICOS!E11,FIND("-",PRONÓSTICOS!E11)+1,10))=RESULTADOS!F11),3,IF(AND(VALUE(LEFT(PRONÓSTICOS!E11,FIND("-",PRONÓSTICOS!E11)-1))-VALUE(MID(PRONÓSTICOS!E11,FIND("-",PRONÓSTICOS!E11)+1,10))=RESULTADOS!E11-RESULTADOS!F11,VALUE(LEFT(PRONÓSTICOS!E11,FIND("-",PRONÓSTICOS!E11)-1))<>RESULTADOS!E11),2,IF(SIGN(VALUE(LEFT(PRONÓSTICOS!E11,FIND("-",PRONÓSTICOS!E11)-1))-VALUE(MID(PRONÓSTICOS!E11,FIND("-",PRONÓSTICOS!E11)+1,10)))=SIGN(RESULTADOS!E11-RESULTADOS!F11),1,0)))) | F10: =IF(OR(RESULTADOS!E11="",RESULTADOS!E11=0,RESULTADOS!F11=""),"—",IF(AND(VALUE(LEFT(PRONÓSTICOS!F11,FIND("-",PRONÓSTICOS!F11)-1))=RESULTADOS!E11,VALUE(MID(PRONÓSTICOS!F11,FIND("-",PRONÓSTICOS!F11)+1,10))=RESULTADOS!F11),3,IF(AND(VALUE(LEFT(PRONÓSTICOS!F11,FIND("-",PRONÓSTICOS!F11)-1))-VALUE(MID(PRONÓSTICOS!F11,FIND("-",PRONÓSTICOS!F11)+1,10))=RESULTADOS!E11-RESULTADOS!F11,VALUE(LEFT(PRONÓSTICOS!F11,FIND("-",PRONÓSTICOS!F11)-1))<>RESULTADOS!E11),2,IF(SIGN(VALUE(LEFT(PRONÓSTICOS!F11,FIND("-",PRONÓSTICOS!F11)-1))-VALUE(MID(PRONÓSTICOS!F11,FIND("-",PRONÓSTICOS!F11)+1,10)))=SIGN(RESULTADOS!E11-RESULTADOS!F11),1,0)))) | G10: =IF(OR(RESULTADOS!E11="",RESULTADOS!E11=0,RESULTADOS!F11=""),"—",IF(AND(VALUE(LEFT(PRONÓSTICOS!G11,FIND("-",PRONÓSTICOS!G11)-1))=RESULTADOS!E11,VALUE(MID(PRONÓSTICOS!G11,FIND("-",PRONÓSTICOS!G11)+1,10))=RESULTADOS!F11),3,IF(AND(VALUE(LEFT(PRONÓSTICOS!G11,FIND("-",PRONÓSTICOS!G11)-1))-VALUE(MID(PRONÓSTICOS!G11,FIND("-",PRONÓSTICOS!G11)+1,10))=RESULTADOS!E11-RESULTADOS!F11,VALUE(LEFT(PRONÓSTICOS!G11,FIND("-",PRONÓSTICOS!G11)-1))<>RESULTADOS!E11),2,IF(SIGN(VALUE(LEFT(PRONÓSTICOS!G11,FIND("-",PRONÓSTICOS!G11)-1))-VALUE(MID(PRONÓSTICOS!G11,FIND("-",PRONÓSTICOS!G11)+1,10)))=SIGN(RESULTADOS!E11-RESULTADOS!F11),1,0)))) | H10: =IF(OR(RESULTADOS!E11="",RESULTADOS!E11=0,RESULTADOS!F11=""),"—",IF(AND(VALUE(LEFT(PRONÓSTICOS!H11,FIND("-",PRONÓSTICOS!H11)-1))=RESULTADOS!E11,VALUE(MID(PRONÓSTICOS!H11,FIND("-",PRONÓSTICOS!H11)+1,10))=RESULTADOS!F11),3,IF(AND(VALUE(LEFT(PRONÓSTICOS!H11,FIND("-",PRONÓSTICOS!H11)-1))-VALUE(MID(PRONÓSTICOS!H11,FIND("-",PRONÓSTICOS!H11)+1,10))=RESULTADOS!E11-RESULTADOS!F11,VALUE(LEFT(PRONÓSTICOS!H11,FIND("-",PRONÓSTICOS!H11)-1))<>RESULTADOS!E11),2,IF(SIGN(VALUE(LEFT(PRONÓSTICOS!H11,FIND("-",PRONÓSTICOS!H11)-1))-VALUE(MID(PRONÓSTICOS!H11,FIND("-",PRONÓSTICOS!H11)+1,10)))=SIGN(RESULTADOS!E11-RESULTADOS!F11),1,0)))) | I10: =IF(OR(RESULTADOS!E11="",RESULTADOS!E11=0,RESULTADOS!F11=""),"—",IF(AND(VALUE(LEFT(PRONÓSTICOS!I11,FIND("-",PRONÓSTICOS!I11)-1))=RESULTADOS!E11,VALUE(MID(PRONÓSTICOS!I11,FIND("-",PRONÓSTICOS!I11)+1,10))=RESULTADOS!F11),3,IF(AND(VALUE(LEFT(PRONÓSTICOS!I11,FIND("-",PRONÓSTICOS!I11)-1))-VALUE(MID(PRONÓSTICOS!I11,FIND("-",PRONÓSTICOS!I11)+1,10))=RESULTADOS!E11-RESULTADOS!F11,VALUE(LEFT(PRONÓSTICOS!I11,FIND("-",PRONÓSTICOS!I11)-1))<>RESULTADOS!E11),2,IF(SIGN(VALUE(LEFT(PRONÓSTICOS!I11,FIND("-",PRONÓSTICOS!I11)-1))-VALUE(MID(PRONÓSTICOS!I11,FIND("-",PRONÓSTICOS!I11)+1,10)))=SIGN(RESULTADOS!E11-RESULTADOS!F11),1,0)))) | J10: =IF(OR(RESULTADOS!E11="",RESULTADOS!E11=0,RESULTADOS!F11=""),"—",IF(AND(VALUE(LEFT(PRONÓSTICOS!J11,FIND("-",PRONÓSTICOS!J11)-1))=RESULTADOS!E11,VALUE(MID(PRONÓSTICOS!J11,FIND("-",PRONÓSTICOS!J11)+1,10))=RESULTADOS!F11),3,IF(AND(VALUE(LEFT(PRONÓSTICOS!J11,FIND("-",PRONÓSTICOS!J11)-1))-VALUE(MID(PRONÓSTICOS!J11,FIND("-",PRONÓSTICOS!J11)+1,10))=RESULTADOS!E11-RESULTADOS!F11,VALUE(LEFT(PRONÓSTICOS!J11,FIND("-",PRONÓSTICOS!J11)-1))<>RESULTADOS!E11),2,IF(SIGN(VALUE(LEFT(PRONÓSTICOS!J11,FIND("-",PRONÓSTICOS!J11)-1))-VALUE(MID(PRONÓSTICOS!J11,FIND("-",PRONÓSTICOS!J11)+1,10)))=SIGN(RESULTADOS!E11-RESULTADOS!F11),1,0)))) | K10: =IF(OR(RESULTADOS!E11="",RESULTADOS!E11=0,RESULTADOS!F11=""),"—",IF(AND(VALUE(LEFT(PRONÓSTICOS!K11,FIND("-",PRONÓSTICOS!K11)-1))=RESULTADOS!E11,VALUE(MID(PRONÓSTICOS!K11,FIND("-",PRONÓSTICOS!K11)+1,10))=RESULTADOS!F11),3,IF(AND(VALUE(LEFT(PRONÓSTICOS!K11,FIND("-",PRONÓSTICOS!K11)-1))-VALUE(MID(PRONÓSTICOS!K11,FIND("-",PRONÓSTICOS!K11)+1,10))=RESULTADOS!E11-RESULTADOS!F11,VALUE(LEFT(PRONÓSTICOS!K11,FIND("-",PRONÓSTICOS!K11)-1))<>RESULTADOS!E11),2,IF(SIGN(VALUE(LEFT(PRONÓSTICOS!K11,FIND("-",PRONÓSTICOS!K11)-1))-VALUE(MID(PRONÓSTICOS!K11,FIND("-",PRONÓSTICOS!K11)+1,10)))=SIGN(RESULTADOS!E11-RESULTADOS!F11),1,0)))) | L10: =IF(OR(RESULTADOS!E11="",RESULTADOS!E11=0,RESULTADOS!F11=""),"—",IF(AND(VALUE(LEFT(PRONÓSTICOS!L11,FIND("-",PRONÓSTICOS!L11)-1))=RESULTADOS!E11,VALUE(MID(PRONÓSTICOS!L11,FIND("-",PRONÓSTICOS!L11)+1,10))=RESULTADOS!F11),3,IF(AND(VALUE(LEFT(PRONÓSTICOS!L11,FIND("-",PRONÓSTICOS!L11)-1))-VALUE(MID(PRONÓSTICOS!L11,FIND("-",PRONÓSTICOS!L11)+1,10))=RESULTADOS!E11-RESULTADOS!F11,VALUE(LEFT(PRONÓSTICOS!L11,FIND("-",PRONÓSTICOS!L11)-1))<>RESULTADOS!E11),2,IF(SIGN(VALUE(LEFT(PRONÓSTICOS!L11,FIND("-",PRONÓSTICOS!L11)-1))-VALUE(MID(PRONÓSTICOS!L11,FIND("-",PRONÓSTICOS!L11)+1,10)))=SIGN(RESULTADOS!E11-RESULTADOS!F11),1,0))))
